Workbook

Sheet Ünnep
A1: Ünnepek:
A2: 43466 | B2: Újév
A3: 43539 | B3: 1848-as forradalom
A4: 43565 | B4: Nagypéntek
A5: 43567 | B5: Húsvét
A6: 43568
A7: 43586 | B7: Munka ünnepe
A8: 43616 | B8: Pünkösd
A9: 43617
A10: 43697 | B10: Államalapítás ünnepe
A11: 43761 | B11: 1956-os forradalom
A12: 43770 | B12: Mindenszentek
A13: 43824 | B13: Karácsony
A14: 43825
A16: változó adat!

Sheet 2020
A1: 2020. év
A3: JANUÁR | B3: 1 | C3: 2 | D3: 3 | E3: 4 | F3: 5 | G3: 6 | H3: 7 | I3: 8 | J3: 9 | K3: 10 | L3: 11 | M3: 12 | N3: 13 | O3: 14 | P3: 15 | Q3: 16 | R3: 17 | S3: 18 | T3: 19 | U3: 20 | V3: 21 | W3: 22 | X3: 23 | Y3: 24 | Z3: 25 | AA3: 26 | AB3: 27 | AC3: 28 | AD3: 29 | AE3: 30 | AF3: 31
B4: Sze | C4: Cs | D4: P | E4: Szo | F4: V | G4: H | H4: K | I4: Sze | J4: Cs | K4: P | L4: Szo | M4: V | N4: H | O4: K | P4: Sze | Q4: Cs | R4: P | S4: Szo | T4: V | U4: H | V4: K | W4: Sze | X4: Cs | Y4: P | Z4: Szo | AA4: V | AB4: H | AC4: K | AD4: Sze | AE4: Cs | AF4: P
A5: "A" műszak | B5: 3 | C5: 3 | D5: X | E5: X | F5: 2 | G5: 2 | H5: 2 | I5: 2 | J5: 2 | K5: 2 | L5: X | M5: X | N5: 1 | O5: 1 | P5: 1 | Q5: 1 | R5: 1 | S5: 1 | T5: X | U5: X | V5: 3 | W5: 3 | X5: 3 | Y5: 3 | Z5: 3 | AA5: 3 | AB5: X | AC5: X | AD5: 2 | AE5: 2 | AF5: 2
A6: "B" műszak | B6: X | C6: X | D6: 3 | E6: 3 | F6: 3 | G6: 3 | H6: 3 | I6: 3 | J6: X | K6: X | L6: 2 | M6: 2 | N6: 2 | O6: 2 | P6: 2 | Q6: 2 | R6: X | S6: X | T6: 1 | U6: 1 | V6: 1 | W6: 1 | X6: 1 | Y6: 1 | Z6: X | AA6: X | AB6: 3 | AC6: 3 | AD6: 3 | AE6: 3 | AF6: 3
A7: "C" műszak | B7: 1 | C7: 1 | D7: 1 | E7: 1 | F7: 1 | G7: 1 | H7: X | I7: X | J7: 3 | K7: 3 | L7: 3 | M7: 3 | N7: 3 | O7: 3 | P7: X | Q7: X | R7: 2 | S7: 2 | T7: 2 | U7: 2 | V7: 2 | W7: 2 | X7: X | Y7: X | Z7: 1 | AA7: 1 | AB7: 1 | AC7: 1 | AD7: 1 | AE7: 1 | AF7: X
A8: "D" műszak | B8: 2 | C8: 2 | D8: 2 | E8: 2 | F8: X | G8: X | H8: 1 | I8: 1 | J8: 1 | K8: 1 | L8: 1 | M8: 1 | N8: X | O8: X | P8: 3 | Q8: 3 | R8: 3 | S8: 3 | T8: 3 | U8: 3 | V8: X | W8: X | X8: 2 | Y8: 2 | Z8: 2 | AA8: 2 | AB8: 2 | AC8: 2 | AD8: X | AE8: X | AF8: 1
A11: FEBRUÁR | B11: 1 | C11: 2 | D11: 3 | E11: 4 | F11: 5 | G11: 6 | H11: 7 | I11: 8 | J11: 9 | K11: 10 | L11: 11 | M11: 12 | N11: 13 | O11: 14 | P11: 15 | Q11: 16 | R11: 17 | S11: 18 | T11: 19 | U11: 20 | V11: 21 | W11: 22 | X11: 23 | Y11: 24 | Z11: 25 | AA11: 26 | AB11: 27 | AC11: 28 | AD11: 29
B12: Szo | C12: V | D12: H | E12: K | F12: Sze | G12: Cs | H12: P | I12: Szo | J12: V | K12: H | L12: K | M12: Sze | N12: Cs | O12: P | P12: Szo | Q12: V | R12: H | S12: K | T12: Sze | U12: Cs | V12: P | W12: Szo | X12: V | Y12: H | Z12: K | AA12: Sze | AB12: Cs | AC12: P | AD12: Szo
A13: "A" műszak | B13: 2 | C13: 2 | D13: 2 | E13: X | F13: X | G13: 1 | H13: 1 | I13: 1 | J13: 1 | K13: 1 | L13: 1 | M13: X | N13: X | O13: 3 | P13: 3 | Q13: 3 | R13: 3 | S13: 3 | T13: 3 | U13: X | V13: X | W13: 2 | X13: 2 | Y13: 2 | Z13: 2 | AA13: 2 | AB13: 2 | AC13: X | AD13: X
A14: "B" műszak | B14: 3 | C14: X | D14: X | E14: 2 | F14: 2 | G14: 2 | H14: 2 | I14: 2 | J14: 2 | K14: X | L14: X | M14: 1 | N14: 1 | O14: 1 | P14: 1 | Q14: 1 | R14: 1 | S14: X | T14: X | U14: 3 | V14: 3 | W14: 3 | X14: 3 | Y14: 3 | Z14: 3 | AA14: X | AB14: X | AC14: 2 | AD14: 2
A15: "C" műszak | B15: X | C15: 3 | D15: 3 | E15: 3 | F15: 3 | G15: 3 | H15: 3 | I15: X | J15: X | K15: 2 | L15: 2 | M15: 2 | N15: 2 | O15: 2 | P15: 2 | Q15: X | R15: X | S15: 1 | T15: 1 | U15: 1 | V15: 1 | W15: 1 | X15: 1 | Y15: X | Z15: X | AA15: 3 | AB15: 3 | AC15: 3 | AD15: 3
A16: "D" műszak | B16: 1 | C16: 1 | D16: 1 | E16: 1 | F16: 1 | G16: X | H16: X | I16: 3 | J16: 3 | K16: 3 | L16: 3 | M16: 3 | N16: 3 | O16: X | P16: X | Q16: 2 | R16: 2 | S16: 2 | T16: 2 | U16: 2 | V16: 2 | W16: X | X16: X | Y16: 1 | Z16: 1 | AA16: 1 | AB16: 1 | AC16: 1 | AD16: 1
A19: MÁRCIUS | B19: 1 | C19: 2 | D19: 3 | E19: 4 | F19: 5 | G19: 6 | H19: 7 | I19: 8 | J19: 9 | K19: 10 | L19: 11 | M19: 12 | N19: 13 | O19: 14 | P19: 15 | Q19: 16 | R19: 17 | S19: 18 | T19: 19 | U19: 20 | V19: 21 | W19: 22 | X19: 23 | Y19: 24 | Z19: 25 | AA19: 26 | AB19: 27 | AC19: 28 | AD19: 29 | AE19: 30 | AF19: 31
B20: V | C20: H | D20: K | E20: Sze | F20: Cs | G20: P | H20: Szo | I20: V | J20: H | K20: K | L20: Sze | M20: Cs | N20: P | O20: Szo | P20: V | Q20: H | R20: K | S20: Sze | T20: Cs | U20: P | V20: Szo | W20: V | X20: H | Y20: K | Z20: Sze | AA20: Cs | AB20: P | AC20: Szo | AD20: V | AE20: H | AF20: K
A21: "A" műszak | B21: 1 | C21: 1 | D21: 1 | E21: 1 | F21: 1 | G21: 1 | H21: X | I21: X | J21: 3 | K21: 3 | L21: 3 | M21: 3 | N21: 3 | O21: 3 | P21: X | Q21: X | R21: 2 | S21: 2 | T21: 2 | U21: 2 | V21: 2 | W21: 2 | X21: X | Y21: X | Z21: 1 | AA21: 1 | AB21: 1 | AC21: 1 | AD21: 1 | AE21: 1 | AF21: X
A22: "B" műszak | B22: 2 | C22: 2 | D22: 2 | E22: 2 | F22: X | G22: X | H22: 1 | I22: 1 | J22: 1 | K22: 1 | L22: 1 | M22: 1 | N22: X | O22: X | P22: 3 | Q22: 3 | R22: 3 | S22: 3 | T22: 3 | U22: 3 | V22: X | W22: X | X22: 2 | Y22: 2 | Z22: 2 | AA22: 2 | AB22: 2 | AC22: 2 | AD22: X | AE22: X | AF22: 1
A23: "C" műszak | B23: 3 | C23: 3 | D23: X | E23: X | F23: 2 | G23: 2 | H23: 2 | I23: 2 | J23: 2 | K23: 2 | L23: X | M23: X | N23: 1 | O23: 1 | P23: 1 | Q23: 1 | R23: 1 | S23: 1 | T23: X | U23: X | V23: 3 | W23: 3 | X23: 3 | Y23: 3 | Z23: 3 | AA23: 3 | AB23: X | AC23: X | AD23: 2 | AE23: 2 | AF23: 2
A24: "D" műszak | B24: X | C24: X | D24: 3 | E24: 3 | F24: 3 | G24: 3 | H24: 3 | I24: 3 | J24: X | K24: X | L24: 2 | M24: 2 | N24: 2 | O24: 2 | P24: 2 | Q24: 2 | R24: X | S24: X | T24: 1 | U24: 1 | V24: 1 | W24: 1 | X24: 1 | Y24: 1 | Z24: X | AA24: X | AB24: 3 | AC24: 3 | AD24: 3 | AE24: 3 | AF24: 3
A27: ÁPRILIS | B27: 1 | C27: 2 | D27: 3 | E27: 4 | F27: 5 | G27: 6 | H27: 7 | I27: 8 | J27: 9 | K27: 10 | L27: 11 | M27: 12 | N27: 13 | O27: 14 | P27: 15 | Q27: 16 | R27: 17 | S27: 18 | T27: 19 | U27: 20 | V27: 21 | W27: 22 | X27: 23 | Y27: 24 | Z27: 25 | AA27: 26 | AB27: 27 | AC27: 28 | AD27: 29 | AE27: 30
B28: Sze | C28: Cs | D28: P | E28: Szo | F28: V | G28: H | H28: K | I28: Sze | J28: Cs | K28: P | L28: Szo | M28: V | N28: H | O28: K | P28: Sze | Q28: Cs | R28: P | S28: Szo | T28: V | U28: H | V28: K | W28: Sze | X28: Cs | Y28: P | Z28: Szo | AA28: V | AB28: H | AC28: K | AD28: Sze | AE28: Cs
A29: "A" műszak | B29: X | C29: 3 | D29: 3 | E29: 3 | F29: 3 | G29: 3 | H29: 3 | I29: X | J29: X | K29: 2 | L29: 2 | M29: 2 | N29: 2 | O29: 2 | P29: 2 | Q29: X | R29: X | S29: 1 | T29: 1 | U29: 1 | V29: 1 | W29: 1 | X29: 1 | Y29: X | Z29: X | AA29: 3 | AB29: 3 | AC29: 3 | AD29: 3 | AE29: 3
A30: "B" műszak | B30: 1 | C30: 1 | D30: 1 | E30: 1 | F30: 1 | G30: X | H30: X | I30: 3 | J30: 3 | K30: 3 | L30: 3 | M30: 3 | N30: 3 | O30: X | P30: X | Q30: 2 | R30: 2 | S30: 2 | T30: 2 | U30: 2 | V30: 2 | W30: X | X30: X | Y30: 1 | Z30: 1 | AA30: 1 | AB30: 1 | AC30: 1 | AD30: 1 | AE30: X
A31: "C" műszak | B31: 2 | C31: 2 | D31: 2 | E31: X | F31: X | G31: 1 | H31: 1 | I31: 1 | J31: 1 | K31: 1 | L31: 1 | M31: X | N31: X | O31: 3 | P31: 3 | Q31: 3 | R31: 3 | S31: 3 | T31: 3 | U31: X | V31: X | W31: 2 | X31: 2 | Y31: 2 | Z31: 2 | AA31: 2 | AB31: 2 | AC31: X | AD31: X | AE31: 1
A32: "D" műszak | B32: 3 | C32: X | D32: X | E32: 2 | F32: 2 | G32: 2 | H32: 2 | I32: 2 | J32: 2 | K32: X | L32: X | M32: 1 | N32: 1 | O32: 1 | P32: 1 | Q32: 1 | R32: 1 | S32: X | T32: X | U32: 3 | V32: 3 | W32: 3 | X32: 3 | Y32: 3 | Z32: 3 | AA32: X | AB32: X | AC32: 2 | AD32: 2 | AE32: 2
A35: MÁJUS | B35: 1 | C35: 2 | D35: 3 | E35: 4 | F35: 5 | G35: 6 | H35: 7 | I35: 8 | J35: 9 | K35: 10 | L35: 11 | M35: 12 | N35: 13 | O35: 14 | P35: 15 | Q35: 16 | R35: 17 | S35: 18 | T35: 19 | U35: 20 | V35: 21 | W35: 22 | X35: 23 | Y35: 24 | Z35: 25 | AA35: 26 | AB35: 27 | AC35: 28 | AD35: 29 | AE35: 30 | AF35: 31
B36: P | C36: Szo | D36: V | E36: H | F36: K | G36: Sze | H36: Cs | I36: P | J36: Szo | K36: V | L36: H | M36: K | N36: Sze | O36: Cs | P36: P | Q36: Szo | R36: V | S36: H | T36: K | U36: Sze | V36: Cs | W36: P | X36: Szo | Y36: V | Z36: H | AA36: K | AB36: Sze | AC36: Cs | AD36: P | AE36: Szo | AF36: V
A37: "A" műszak | B37: 3 | C37: X | D37: X | E37: 2 | F37: 2 | G37: 2 | H37: 2 | I37: 2 | J37: 2 | K37: X | L37: X | M37: 1 | N37: 1 | O37: 1 | P37: 1 | Q37: 1 | R37: 1 | S37: X | T37: X | U37: 3 | V37: 3 | W37: 3 | X37: 3 | Y37: 3 | Z37: 3 | AA37: X | AB37: X | AC37: 2 | AD37: 2 | AE37: 2 | AF37: 2
A38: "B" műszak | B38: X | C38: 3 | D38: 3 | E38: 3 | F38: 3 | G38: 3 | H38: 3 | I38: X | J38: X | K38: 2 | L38: 2 | M38: 2 | N38: 2 | O38: 2 | P38: 2 | Q38: X | R38: X | S38: 1 | T38: 1 | U38: 1 | V38: 1 | W38: 1 | X38: 1 | Y38: X | Z38: X | AA38: 3 | AB38: 3 | AC38: 3 | AD38: 3 | AE38: 3 | AF38: 3
A39: "C" műszak | B39: 1 | C39: 1 | D39: 1 | E39: 1 | F39: 1 | G39: X | H39: X | I39: 3 | J39: 3 | K39: 3 | L39: 3 | M39: 3 | N39: 3 | O39: X | P39: X | Q39: 2 | R39: 2 | S39: 2 | T39: 2 | U39: 2 | V39: 2 | W39: X | X39: X | Y39: 1 | Z39: 1 | AA39: 1 | AB39: 1 | AC39: 1 | AD39: 1 | AE39: X | AF39: X
A40: "D" műszak | B40: 2 | C40: 2 | D40: 2 | E40: X | F40: X | G40: 1 | H40: 1 | I40: 1 | J40: 1 | K40: 1 | L40: 1 | M40: X | N40: X | O40: 3 | P40: 3 | Q40: 3 | R40: 3 | S40: 3 | T40: 3 | U40: X | V40: X | W40: 2 | X40: 2 | Y40: 2 | Z40: 2 | AA40: 2 | AB40: 2 | AC40: X | AD40: X | AE40: 1 | AF40: 1
A43: JÚNIUS | B43: 1 | C43: 2 | D43: 3 | E43: 4 | F43: 5 | G43: 6 | H43: 7 | I43: 8 | J43: 9 | K43: 10 | L43: 11 | M43: 12 | N43: 13 | O43: 14 | P43: 15 | Q43: 16 | R43: 17 | S43: 18 | T43: 19 | U43: 20 | V43: 21 | W43: 22 | X43: 23 | Y43: 24 | Z43: 25 | AA43: 26 | AB43: 27 | AC43: 28 | AD43: 29 | AE43: 30
B44: H | C44: K | D44: Sze | E44: Cs | F44: P | G44: Szo | H44: V | I44: H | J44: K | K44: Sze | L44: Cs | M44: P | N44: Szo | O44: V | P44: H | Q44: K | R44: Sze | S44: Cs | T44: P | U44: Szo | V44: V | W44: H | X44: K | Y44: Sze | Z44: Cs | AA44: P | AB44: Szo | AC44: V | AD44: H | AE44: K
A45: "A" műszak | B45: 2 | C45: 2 | D45: X | E45: X | F45: 1 | G45: 1 | H45: 1 | I45: 1 | J45: 1 | K45: 1 | L45: X | M45: X | N45: 3 | O45: 3 | P45: 3 | Q45: 3 | R45: 3 | S45: 3 | T45: X | U45: X | V45: 2 | W45: 2 | X45: 2 | Y45: 2 | Z45: 2 | AA45: 2 | AB45: X | AC45: X | AD45: 1 | AE45: 1
A46: "B" műszak | B46: X | C46: X | D46: 2 | E46: 2 | F46: 2 | G46: 2 | H46: 2 | I46: 2 | J46: X | K46: X | L46: 1 | M46: 1 | N46: 1 | O46: 1 | P46: 1 | Q46: 1 | R46: X | S46: X | T46: 3 | U46: 3 | V46: 3 | W46: 3 | X46: 3 | Y46: 3 | Z46: X | AA46: X | AB46: 2 | AC46: 2 | AD46: 2 | AE46: 2
A47: "C" műszak | B47: 3 | C47: 3 | D47: 3 | E47: 3 | F47: 3 | G47: 3 | H47: X | I47: X | J47: 2 | K47: 2 | L47: 2 | M47: 2 | N47: 2 | O47: 2 | P47: X | Q47: X | R47: 1 | S47: 1 | T47: 1 | U47: 1 | V47: 1 | W47: 1 | X47: X | Y47: X | Z47: 3 | AA47: 3 | AB47: 3 | AC47: 3 | AD47: 3 | AE47: 3
A48: "D" műszak | B48: 1 | C48: 1 | D48: 1 | E48: 1 | F48: X | G48: X | H48: 3 | I48: 3 | J48: 3 | K48: 3 | L48: 3 | M48: 3 | N48: X | O48: X | P48: 2 | Q48: 2 | R48: 2 | S48: 2 | T48: 2 | U48: 2 | V48: X | W48: X | X48: 1 | Y48: 1 | Z48: 1 | AA48: 1 | AB48: 1 | AC48: 1 | AD48: X | AE48: X
A51: JÚLIUS | B51: 1 | C51: 2 | D51: 3 | E51: 4 | F51: 5 | G51: 6 | H51: 7 | I51: 8 | J51: 9 | K51: 10 | L51: 11 | M51: 12 | N51: 13 | O51: 14 | P51: 15 | Q51: 16 | R51: 17 | S51: 18 | T51: 19 | U51: 20 | V51: 21 | W51: 22 | X51: 23 | Y51: 24 | Z51: 25 | AA51: 26 | AB51: 27 | AC51: 28 | AD51: 29 | AE51: 30 | AF51: 31
B52: Sze | C52: Cs | D52: P | E52: Szo | F52: V | G52: H | H52: K | I52: Sze | J52: Cs | K52: P | L52: Szo | M52: V | N52: H | O52: K | P52: Sze | Q52: Cs | R52: P | S52: Szo | T52: V | U52: H | V52: K | W52: Sze | X52: Cs | Y52: P | Z52: Szo | AA52: V | AB52: H | AC52: K | AD52: Sze | AE52: Cs | AF52: P
A53: "A" műszak | B53: 1 | C53: 1 | D53: 1 | E53: 1 | F53: X | G53: X | H53: 3 | I53: 3 | J53: 3 | K53: 3 | L53: 3 | M53: 3 | N53: X | O53: X | P53: 2 | Q53: 2 | R53: 2 | S53: 2 | T53: 2 | U53: 2 | V53: X | W53: X | X53: 1 | Y53: 1 | Z53: 1 | AA53: 1 | AB53: 1 | AC53: 1 | AD53: X | AE53: X | AF53: 3
...

Sheet ÖSSZES
A1: N é v | B1: Áth. | C1: 2020 | D1: Gye-rek | E1: Össz. | F1: I. | G1: II. | H1: III. | I1: IV. | J1: V. | K1: VI. | L1: VII | M1: VIII | N1: IX | O1: X | P1: XI | Q1: XII | R1: Szf | S1: M. | U1: I. | V1: II | W1: III | X1: IV | Y1: V | Z1: VI | AA1: VII | AB1: VIII | AC1: IX | AD1: X | AE1: XI | AF1: XII | AG1: + | AH1: M.
F2: szf | G2: szf | H2: szf | I2: szf | J2: szf | K2: szf | L2: szf | M2: szf | N2: szf | O2: szf | P2: szf | Q2: szf | S2: szf | U2: + | V2: + | W2: + | X2: + | Y2: + | Z2: + | AA2: + | AB2: + | AC2: + | AD2: + | AE2: + | AF2: + | AH2: +
A3: Csuka Lajos | C3: 30 | E3: =SUM(B3:D3) -> 30 | F3: =A!AI4 -> 1 | G3: =A!AI28 -> 1 | H3: =A!AI52 -> 3 | I3: =A!AI76 -> 1 | J3: =A!AI100 -> 0 | K3: =A!AI124 -> 0 | L3: =A!AI148 -> 0 | M3: =A!AI172 -> 0 | N3: =A!AI196 -> 0 | O3: =A!AI220 -> 0 | P3: =A!AI244 -> 0 | Q3: =A!AI268 -> 0 | R3: =SUM(F3+G3+H3+I3+J3+K3+L3+M3+N3+O3+P3+Q3) -> 6 | S3: =SUM(E3-R3) -> 24 | U3: =A!AH4 -> 1 | V3: =A!AH28 -> 1 | W3: =A!AH52 -> 2 | X3: =A!AH76 -> 1 | Y3: =A!AH100 -> 0 | Z3: =A!AH124 -> 0 | AA3: =A!AH148 -> 0 | AB3: =A!AH172 -> 0 | AC3: =A!AH196 -> 0 | AD3: =A!AH220 -> 0 | AE3: =A!AH244 -> 0 | AF3: =A!AH268 -> 0 | AG3: =SUM(U3+V3+W3+X3+Y3+Z3+AA3+AB3+AC3+AD3+AE3+AF3) -> 5 | AH3: =SUM(16-AG3) -> 11
A4: Batiz Attila | C4: 25 | E4: =SUM(B4:D4) -> 25 | F4: =A!AI5 -> 0 | G4: =A!AI29 -> 0 | H4: =A!AI53 -> 0 | I4: =A!AI77 -> 0 | J4: =A!AI101 -> 0 | K4: =A!AI125 -> 0 | L4: =A!AI149 -> 0 | M4: =A!AI173 -> 0 | N4: =A!AI197 -> 0 | O4: =A!AI221 -> 0 | P4: =A!AI245 -> 0 | Q4: =A!AI269 -> 0 | R4: =SUM(F4+G4+H4+I4+J4+K4+L4+M4+N4+O4+P4+Q4) -> 0 | S4: =SUM(E4-R4) -> 25 | U4: =A!AH5 -> 1 | V4: =A!AH29 -> 2 | W4: =A!AH53 -> 0 | X4: =A!AH77 -> 2 | Y4: =A!AH101 -> 0 | Z4: =A!AH125 -> 0 | AA4: =A!AH149 -> 0 | AB4: =A!AH173 -> 0 | AC4: =A!AH197 -> 0 | AD4: =A!AH221 -> 0 | AE4: =A!AH245 -> 0 | AF4: =A!AH269 -> 0 | AG4: =SUM(U4+V4+W4+X4+Y4+Z4+AA4+AB4+AC4+AD4+AE4+AF4) -> 5 | AH4: =SUM(16-AG4) -> 11
A5: Mizsák Péter | B5: 1 | C5: 21 | E5: =SUM(B5:D5) -> 22 | F5: =A!AI6 -> 1 | G5: =A!AI30 -> 0 | H5: =A!AI54 -> 0 | I5: =A!AI78 -> 1 | J5: =A!AI102 -> 0 | K5: =A!AI126 -> 0 | L5: =A!AI150 -> 0 | M5: =A!AI174 -> 0 | N5: =A!AI198 -> 0 | O5: =A!AI222 -> 0 | P5: =A!AI246 -> 0 | Q5: =A!AI270 -> 0 | R5: =SUM(F5+G5+H5+I5+J5+K5+L5+M5+N5+O5+P5+Q5) -> 2 | S5: =SUM(E5-R5) -> 20 | U5: =A!AH6 -> 1 | V5: =A!AH30 -> 0 | W5: =A!AH54 -> 1 | X5: =A!AH78 -> 2 | Y5: =A!AH102 -> 0 | Z5: =A!AH126 -> 0 | AA5: =A!AH150 -> 0 | AB5: =A!AH174 -> 0 | AC5: =A!AH198 -> 0 | AD5: =A!AH222 -> 0 | AE5: =A!AH246 -> 0 | AF5: =A!AH270 -> 0 | AG5: =SUM(U5+V5+W5+X5+Y5+Z5+AA5+AB5+AC5+AD5+AE5+AF5) -> 4 | AH5: =SUM(16-AG5) -> 12
A6: Füredi Antal | C6: 25 | D6: 4 | E6: =SUM(B6:D6) -> 29 | F6: =A!AI7 -> 0 | G6: =A!AI31 -> 1 | H6: =A!AI55 -> 0 | I6: =A!AI79 -> 0 | J6: =A!AI103 -> 3 | K6: =A!AI127 -> 0 | L6: =A!AI151 -> 0 | M6: =A!AI175 -> 0 | N6: =A!AI199 -> 0 | O6: =A!AI223 -> 0 | P6: =A!AI247 -> 0 | Q6: =A!AI271 -> 0 | R6: =SUM(F6+G6+H6+I6+J6+K6+L6+M6+N6+O6+P6+Q6) -> 4 | S6: =SUM(E6-R6) -> 25 | U6: =A!AH7 -> 0 | V6: =A!AH31 -> 1 | W6: =A!AH55 -> 0 | X6: =A!AH79 -> 0 | Y6: =A!AH103 -> 3 | Z6: =A!AH127 -> 0 | AA6: =A!AH151 -> 0 | AB6: =A!AH175 -> 0 | AC6: =A!AH199 -> 0 | AD6: =A!AH223 -> 0 | AE6: =A!AH247 -> 0 | AF6: =A!AH271 -> 0 | AG6: =SUM(U6+V6+W6+X6+Y6+Z6+AA6+AB6+AC6+AD6+AE6+AF6) -> 4 | AH6: =SUM(16-AG6) -> 12
A7: Iványi István | C7: 23 | E7: =SUM(B7:D7) -> 23 | F7: =A!AI8 -> 1 | G7: =A!AI32 -> 3 | H7: =A!AI56 -> 2 | I7: =A!AI80 -> 0 | J7: =A!AI104 -> 1 | K7: =A!AI128 -> 0 | L7: =A!AI152 -> 0 | M7: =A!AI176 -> 0 | N7: =A!AI200 -> 0 | O7: =A!AI224 -> 0 | P7: =A!AI248 -> 0 | Q7: =A!AI272 -> 0 | R7: =SUM(F7+G7+H7+I7+J7+K7+L7+M7+N7+O7+P7+Q7) -> 7 | S7: =SUM(E7-R7) -> 16 | U7: =A!AH8 -> 1 | V7: =A!AH32 -> 1 | W7: =A!AH56 -> 1 | X7: =A!AH80 -> 0 | Y7: =A!AH104 -> 1 | Z7: =A!AH128 -> 0 | AA7: =A!AH152 -> 0 | AB7: =A!AH176 -> 0 | AC7: =A!AH200 -> 0 | AD7: =A!AH224 -> 0 | AE7: =A!AH248 -> 0 | AF7: =A!AH272 -> 0 | AG7: =SUM(U7+V7+W7+X7+Y7+Z7+AA7+AB7+AC7+AD7+AE7+AF7) -> 4 | AH7: =SUM(16-AG7) -> 12
A8: Katonka Tibor | C8: 25 | E8: =SUM(B8:D8) -> 25 | F8: =A!AI9 -> 0 | G8: =A!AI33 -> 0 | H8: =A!AI57 -> 0 | I8: =A!AI81 -> 1 | J8: =A!AI105 -> 1 | K8: =A!AI129 -> 0 | L8: =A!AI153 -> 0 | M8: =A!AI177 -> 0 | N8: =A!AI201 -> 0 | O8: =A!AI225 -> 0 | P8: =A!AI249 -> 0 | Q8: =A!AI273 -> 0 | R8: =SUM(F8+G8+H8+I8+J8+K8+L8+M8+N8+O8+P8+Q8) -> 2 | S8: =SUM(E8-R8) -> 23 | U8: =A!AH9 -> 1 | V8: =A!AH33 -> 1 | W8: =A!AH57 -> 0 | X8: =A!AH81 -> 2 | Y8: =A!AH105 -> 0 | Z8: =A!AH129 -> 0 | AA8: =A!AH153 -> 0 | AB8: =A!AH177 -> 0 | AC8: =A!AH201 -> 0 | AD8: =A!AH225 -> 0 | AE8: =A!AH249 -> 0 | AF8: =A!AH273 -> 0 | AG8: =SUM(U8+V8+W8+X8+Y8+Z8+AA8+AB8+AC8+AD8+AE8+AF8) -> 4 | AH8: =SUM(16-AG8) -> 12
A9: Kiss János Tamás | C9: 30 | E9: =SUM(B9:D9) -> 30 | F9: =A!AI10 -> 0 | G9: =A!AI34 -> 0 | H9: =A!AI58 -> 0 | I9: =A!AI82 -> 0 | J9: =A!AI106 -> 0 | K9: =A!AI130 -> 0 | L9: =A!AI154 -> 0 | M9: =A!AI178 -> 0 | N9: =A!AI202 -> 0 | O9: =A!AI226 -> 0 | P9: =A!AI250 -> 0 | Q9: =A!AI274 -> 0 | R9: =SUM(F9+G9+H9+I9+J9+K9+L9+M9+N9+O9+P9+Q9) -> 0 | S9: =SUM(E9-R9) -> 30 | U9: =A!AH10 -> 1 | V9: =A!AH34 -> 1 | W9: =A!AH58 -> 0 | X9: =A!AH82 -> 0 | Y9: =A!AH106 -> 0 | Z9: =A!AH130 -> 0 | AA9: =A!AH154 -> 0 | AB9: =A!AH178 -> 0 | AC9: =A!AH202 -> 0 | AD9: =A!AH226 -> 0 | AE9: =A!AH250 -> 0 | AF9: =A!AH274 -> 0 | AG9: =SUM(U9+V9+W9+X9+Y9+Z9+AA9+AB9+AC9+AD9+AE9+AF9) -> 2 | AH9: =SUM(16-AG9) -> 14
A10: Vatamány Gergő | C10: 21 | E10: =SUM(B10:D10) -> 21 | F10: =A!AI11 -> 0 | G10: =A!AI35 -> 0 | H10: =A!AI59 -> 0 | I10: =A!AI83 -> 0 | J10: =A!AI107 -> 0 | K10: =A!AI131 -> 0 | L10: =A!AI155 -> 0 | M10: =A!AI179 -> 0 | N10: =A!AI203 -> 0 | O10: =A!AI227 -> 0 | P10: =A!AI251 -> 0 | Q10: =A!AI275 -> 0 | R10: =SUM(F10+G10+H10+I10+J10+K10+L10+M10+N10+O10+P10+Q10) -> 0 | S10: =SUM(E10-R10) -> 21 | U10: =A!AH11 -> 0 | V10: =A!AH35 -> 0 | W10: =A!AH59 -> 3 | X10: =A!AH83 -> 0 | Y10: =A!AH107 -> 0 | Z10: =A!AH131 -> 0 | AA10: =A!AH155 -> 0 | AB10: =A!AH179 -> 0 | AC10: =A!AH203 -> 0 | AD10: =A!AH227 -> 0 | AE10: =A!AH251 -> 0 | AF10: =A!AH275 -> 0 | AG10: =SUM(U10+V10+W10+X10+Y10+Z10+AA10+AB10+AC10+AD10+AE10+AF10) -> 3 | AH10: =SUM(16-AG10) -> 13
A11: Név9 | E11: =SUM(B11:D11) -> 0 | F11: =A!AI12 -> 0 | G11: =A!AI36 -> 0 | H11: =A!AI60 -> 0 | I11: =A!AI84 -> 0 | J11: =A!AI108 -> 0 | K11: =A!AI132 -> 0 | L11: =A!AI156 -> 0 | M11: =A!AI180 -> 0 | N11: =A!AI204 -> 0 | O11: =A!AI228 -> 0 | P11: =A!AI252 -> 0 | Q11: =A!AI276 -> 0 | R11: =SUM(F11+G11+H11+I11+J11+K11+L11+M11+N11+O11+P11+Q11) -> 0 | S11: =SUM(E11-R11) -> 0 | U11: =A!AH12 -> 0 | V11: =A!AH36 -> 0 | W11: =A!AH60 -> 0 | X11: =A!AH84 -> 0 | Y11: =A!AH108 -> 0 | Z11: =A!AH132 -> 0 | AA11: =A!AH156 -> 0 | AB11: =A!AH180 -> 0 | AC11: =A!AH204 -> 0 | AD11: =A!AH228 -> 0 | AE11: =A!AH252 -> 0 | AF11: =A!AH276 -> 0 | AG11: =SUM(U11+V11+W11+X11+Y11+Z11+AA11+AB11+AC11+AD11+AE11+AF11) -> 0 | AH11: =SUM(13-AG11) -> 13
A12: Név10 | E12: =SUM(B12:D12) -> 0 | F12: =A!AI13 -> 0 | G12: =A!AI37 -> 0 | H12: =A!AI61 -> 0 | I12: =A!AI85 -> 0 | J12: =A!AI109 -> 0 | K12: =A!AI133 -> 0 | L12: =A!AI157 -> 0 | M12: =A!AI181 -> 0 | N12: =A!AI205 -> 0 | O12: =A!AI229 -> 0 | P12: =A!AI253 -> 0 | Q12: =A!AI277 -> 0 | R12: =SUM(F12+G12+H12+I12+J12+K12+L12+M12+N12+O12+P12+Q12) -> 0 | S12: =SUM(E12-R12) -> 0 | U12: =A!AH13 -> 0 | V12: =A!AH37 -> 0 | W12: =A!AH61 -> 0 | X12: =A!AH85 -> 0 | Y12: =A!AH109 -> 0 | Z12: =A!AH133 -> 0 | AA12: =A!AH157 -> 0 | AB12: =A!AH181 -> 0 | AC12: =A!AH205 -> 0 | AD12: =A!AH229 -> 0 | AE12: =A!AH253 -> 0 | AF12: =A!AH277 -> 0 | AG12: =SUM(U12+V12+W12+X12+Y12+Z12+AA12+AB12+AC12+AD12+AE12+AF12) -> 0 | AH12: =SUM(13-AG12) -> 13
A13: Név11 | E13: =SUM(B13:D13) -> 0 | F13: =A!AI14 -> 0 | G13: =A!AI38 -> 0 | H13: =A!AI62 -> 0 | I13: =A!AI86 -> 0 | J13: =A!AI110 -> 0 | K13: =A!AI134 -> 0 | L13: =A!AI158 -> 0 | M13: =A!AI182 -> 0 | N13: =A!AI206 -> 0 | O13: =A!AI230 -> 0 | P13: =A!AI254 -> 0 | Q13: =A!AI278 -> 0 | R13: =SUM(F13+G13+H13+I13+J13+K13+L13+M13+N13+O13+P13+Q13) -> 0 | S13: =SUM(E13-R13) -> 0 | U13: =A!AH14 -> 0 | V13: =A!AH38 -> 0 | W13: =A!AH62 -> 0 | X13: =A!AH86 -> 0 | Y13: =A!AH110 -> 0 | Z13: =A!AH134 -> 0 | AA13: =A!AH158 -> 0 | AB13: =A!AH182 -> 0 | AC13: =A!AH206 -> 0 | AD13: =A!AH230 -> 0 | AE13: =A!AH254 -> 0 | AF13: =A!AH278 -> 0 | AG13: =SUM(U13+V13+W13+X13+Y13+Z13+AA13+AB13+AC13+AD13+AE13+AF13) -> 0 | AH13: =SUM(13-AG13) -> 13
A14: Név12 | E14: =SUM(B14:D14) -> 0 | F14: =A!AI15 -> 0 | G14: =A!AI39 -> 0 | H14: =A!AI63 -> 0 | I14: =A!AI87 -> 0 | J14: =A!AI111 -> 0 | K14: =A!AI135 -> 0 | L14: =A!AI159 -> 0 | M14: =A!AI183 -> 0 | N14: =A!AI207 -> 0 | O14: =A!AI231 -> 0 | P14: =A!AI255 -> 0 | Q14: =A!AI279 -> 0 | R14: =SUM(F14+G14+H14+I14+J14+K14+L14+M14+N14+O14+P14+Q14) -> 0 | S14: =SUM(E14-R14) -> 0 | U14: =A!AH15 -> 0 | V14: =A!AH39 -> 0 | W14: =A!AH63 -> 0 | X14: =A!AH87 -> 0 | Y14: =A!AH111 -> 0 | Z14: =A!AH135 -> 0 | AA14: =A!AH159 -> 0 | AB14: =A!AH183 -> 0 | AC14: =A!AH207 -> 0 | AD14: =A!AH231 -> 0 | AE14: =A!AH255 -> 0 | AF14: =A!AH279 -> 0 | AG14: =SUM(U14+V14+W14+X14+Y14+Z14+AA14+AB14+AC14+AD14+AE14+AF14) -> 0 | AH14: =SUM(13-AG14) -> 13
A15: Név13 | E15: =SUM(B15:D15) -> 0 | F15: =A!AI16 -> 0 | G15: =A!AI40 -> 0 | H15: =A!AI64 -> 0 | I15: =A!AI88 -> 0 | J15: =A!AI112 -> 0 | K15: =A!AI136 -> 0 | L15: =A!AI160 -> 0 | M15: =A!AI184 -> 0 | N15: =A!AI208 -> 0 | O15: =A!AI232 -> 0 | P15: =A!AI256 -> 0 | Q15: =A!AI280 -> 0 | R15: =SUM(F15+G15+H15+I15+J15+K15+L15+M15+N15+O15+P15+Q15) -> 0 | S15: =SUM(E15-R15) -> 0 | U15: =A!AH16 -> 0 | V15: =A!AH40 -> 0 | W15: =A!AH64 -> 0 | X15: =A!AH88 -> 0 | Y15: =A!AH112 -> 0 | Z15: =A!AH136 -> 0 | AA15: =A!AH160 -> 0 | AB15: =A!AH184 -> 0 | AC15: =A!AH208 -> 0 | AD15: =A!AH232 -> 0 | AE15: =A!AH256 -> 0 | AF15: =A!AH280 -> 0 | AG15: =SUM(U15+V15+W15+X15+Y15+Z15+AA15+AB15+AC15+AD15+AE15+AF15) -> 0 | AH15: =SUM(13-AG15) -> 13
A16: Név14 | E16: =SUM(B16:D16) -> 0 | F16: =A!AI17 -> 0 | G16: =A!AI41 -> 0 | H16: =A!AI65 -> 0 | I16: =A!AI89 -> 0 | J16: =A!AI113 -> 0 | K16: =A!AI137 -> 0 | L16: =A!AI161 -> 0 | M16: =A!AI185 -> 0 | N16: =A!AI209 -> 0 | O16: =A!AI233 -> 0 | P16: =A!AI257 -> 0 | Q16: =A!AI281 -> 0 | R16: =SUM(F16+G16+H16+I16+J16+K16+L16+M16+N16+O16+P16+Q16) -> 0 | S16: =SUM(E16-R16) -> 0 | U16: =A!AH17 -> 0 | V16: =A!AH41 -> 0 | W16: =A!AH65 -> 0 | X16: =A!AH89 -> 0 | Y16: =A!AH113 -> 0 | Z16: =A!AH137 -> 0 | AA16: =A!AH161 -> 0 | AB16: =A!AH185 -> 0 | AC16: =A!AH209 -> 0 | AD16: =A!AH233 -> 0 | AE16: =A!AH257 -> 0 | AF16: =A!AH281 -> 0 | AG16: =SUM(U16+V16+W16+X16+Y16+Z16+AA16+AB16+AC16+AD16+AE16+AF16) -> 0 | AH16: =SUM(13-AG16) -> 13
A17: Név15 | E17: =SUM(B17:D17) -> 0 | F17: =A!AI18 -> 0 | G17: =A!AI42 -> 0 | H17: =A!AI66 -> 0 | I17: =A!AI90 -> 0 | J17: =A!AI114 -> 0 | K17: =A!AI138 -> 0 | L17: =A!AI162 -> 0 | M17: =A!AI186 -> 0 | N17: =A!AI210 -> 0 | O17: =A!AI234 -> 0 | P17: =A!AI258 -> 0 | Q17: =A!AI282 -> 0 | R17: =SUM(F17+G17+H17+I17+J17+K17+L17+M17+N17+O17+P17+Q17) -> 0 | S17: =SUM(E17-R17) -> 0 | U17: =A!AH18 -> 0 | V17: =A!AH42 -> 0 | W17: =A!AH66 -> 0 | X17: =A!AH90 -> 0 | Y17: =A!AH114 -> 0 | Z17: =A!AH138 -> 0 | AA17: =A!AH162 -> 0 | AB17: =A!AH186 -> 0 | AC17: =A!AH210 -> 0 | AD17: =A!AH234 -> 0 | AE17: =A!AH258 -> 0 | AF17: =A!AH282 -> 0 | AG17: =SUM(U17+V17+W17+X17+Y17+Z17+AA17+AB17+AC17+AD17+AE17+AF17) -> 0 | AH17: =SUM(13-AG17) -> 13
A18: Név16 | E18: =SUM(B18:D18) -> 0 | F18: =A!AI19 -> 0 | G18: =A!AI43 -> 0 | H18: =A!AI67 -> 0 | I18: =A!AI91 -> 0 | J18: =A!AI115 -> 0 | K18: =A!AI139 -> 0 | L18: =A!AI163 -> 0 | M18: =A!AI187 -> 0 | N18: =A!AI211 -> 0 | O18: =A!AI235 -> 0 | P18: =A!AI259 -> 0 | Q18: =A!AI283 -> 0 | R18: =SUM(F18+G18+H18+I18+J18+K18+L18+M18+N18+O18+P18+Q18) -> 0 | S18: =SUM(E18-R18) -> 0 | U18: =A!AH19 -> 0 | V18: =A!AH43 -> 0 | W18: =A!AH67 -> 0 | X18: =A!AH91 -> 0 | Y18: =A!AH115 -> 0 | Z18: =A!AH139 -> 0 | AA18: =A!AH163 -> 0 | AB18: =A!AH187 -> 0 | AC18: =A!AH211 -> 0 | AD18: =A!AH235 -> 0 | AE18: =A!AH259 -> 0 | AF18: =A!AH283 -> 0 | AG18: =SUM(U18+V18+W18+X18+Y18+Z18+AA18+AB18+AC18+AD18+AE18+AF18) -> 0 | AH18: =SUM(13-AG18) -> 13
A19: Név17 | E19: =SUM(B19:D19) -> 0 | F19: =A!AI20 -> 0 | G19: =A!AI44 -> 0 | H19: =A!AI68 -> 0 | I19: =A!AI92 -> 0 | J19: =A!AI116 -> 0 | K19: =A!AI140 -> 0 | L19: =A!AI164 -> 0 | M19: =A!AI188 -> 0 | N19: =A!AI212 -> 0 | O19: =A!AI236 -> 0 | P19: =A!AI260 -> 0 | Q19: =A!AI284 -> 0 | R19: =SUM(F19+G19+H19+I19+J19+K19+L19+M19+N19+O19+P19+Q19) -> 0 | S19: =SUM(E19-R19) -> 0 | U19: =A!AH20 -> 0 | V19: =A!AH44 -> 0 | W19: =A!AH68 -> 0 | X19: =A!AH92 -> 0 | Y19: =A!AH116 -> 0 | Z19: =A!AH140 -> 0 | AA19: =A!AH164 -> 0 | AB19: =A!AH188 -> 0 | AC19: =A!AH212 -> 0 | AD19: =A!AH236 -> 0 | AE19: =A!AH260 -> 0 | AF19: =A!AH284 -> 0 | AG19: =SUM(U19+V19+W19+X19+Y19+Z19+AA19+AB19+AC19+AD19+AE19+AF19) -> 0 | AH19: =SUM(13-AG19) -> 13
A20: Név18 | E20: =SUM(B20:D20) -> 0 | F20: =A!AI21 -> 0 | G20: =A!AI45 -> 0 | H20: =A!AI69 -> 0 | I20: =A!AI93 -> 0 | J20: =A!AI117 -> 0 | K20: =A!AI141 -> 0 | L20: =A!AI165 -> 0 | M20: =A!AI189 -> 0 | N20: =A!AI213 -> 0 | O20: =A!AI237 -> 0 | P20: =A!AI261 -> 0 | Q20: =A!AI285 -> 0 | R20: =SUM(F20+G20+H20+I20+J20+K20+L20+M20+N20+O20+P20+Q20) -> 0 | S20: =SUM(E20-R20) -> 0 | U20: =A!AH21 -> 0 | V20: =A!AH45 -> 0 | W20: =A!AH69 -> 0 | X20: =A!AH93 -> 0 | Y20: =A!AH117 -> 0 | Z20: =A!AH141 -> 0 | AA20: =A!AH165 -> 0 | AB20: =A!AH189 -> 0 | AC20: =A!AH213 -> 0 | AD20: =A!AH237 -> 0 | AE20: =A!AH261 -> 0 | AF20: =A!AH285 -> 0 | AG20: =SUM(U20+V20+W20+X20+Y20+Z20+AA20+AB20+AC20+AD20+AE20+AF20) -> 0 | AH20: =SUM(13-AG20) -> 13
A21: Név19 | E21: =SUM(B21:D21) -> 0 | F21: =A!AI22 -> 0 | G21: =A!AI46 -> 0 | H21: =A!AI70 -> 0 | I21: =A!AI94 -> 0 | J21: =A!AI118 -> 0 | K21: =A!AI142 -> 0 | L21: =A!AI166 -> 0 | M21: =A!AI190 -> 0 | N21: =A!AI214 -> 0 | O21: =A!AI238 -> 0 | P21: =A!AI262 -> 0 | Q21: =A!AI286 -> 0 | R21: =SUM(F21+G21+H21+I21+J21+K21+L21+M21+N21+O21+P21+Q21) -> 0 | S21: =SUM(E21-R21) -> 0 | U21: =A!AH22 -> 0 | V21: =A!AH46 -> 0 | W21: =A!AH70 -> 0 | X21: =A!AH94 -> 0 | Y21: =A!AH118 -> 0 | Z21: =A!AH142 -> 0 | AA21: =A!AH166 -> 0 | AB21: =A!AH190 -> 0 | AC21: =A!AH214 -> 0 | AD21: =A!AH238 -> 0 | AE21: =A!AH262 -> 0 | AF21: =A!AH286 -> 0 | AG21: =SUM(U21+V21+W21+X21+Y21+Z21+AA21+AB21+AC21+AD21+AE21+AF21) -> 0 | AH21: =SUM(13-AG21) -> 13
A22: Név20 | E22: =SUM(B22:D22) -> 0 | F22: =A!AI23 -> 0 | G22: =A!AI47 -> 0 | H22: =A!AI71 -> 0 | I22: =A!AI95 -> 0 | J22: =A!AI119 -> 0 | K22: =A!AI143 -> 0 | L22: =A!AI167 -> 0 | M22: =A!AI191 -> 0 | N22: =A!AI215 -> 0 | O22: =A!AI239 -> 0 | P22: =A!AI263 -> 0 | Q22: =A!AI287 -> 0 | R22: =SUM(F22+G22+H22+I22+J22+K22+L22+M22+N22+O22+P22+Q22) -> 0 | S22: =SUM(E22-R22) -> 0 | U22: =A!AH23 -> 0 | V22: =A!AH47 -> 0 | W22: =A!AH71 -> 0 | X22: =A!AH95 -> 0 | Y22: =A!AH119 -> 0 | Z22: =A!AH143 -> 0 | AA22: =A!AH167 -> 0 | AB22: =A!AH191 -> 0 | AC22: =A!AH215 -> 0 | AD22: =A!AH239 -> 0 | AE22: =A!AH263 -> 0 | AF22: =A!AH287 -> 0 | AG22: =SUM(U22+V22+W22+X22+Y22+Z22+AA22+AB22+AC22+AD22+AE22+AF22) -> 0 | AH22: =SUM(13-AG22) -> 13
A24: N é v | B24: Áth. | C24: 2020 | D24: Gye-rek | E24: Össz. | F24: I. | G24: II. | H24: III. | I24: IV. | J24: V. | K24: VI. | L24: VII | M24: VIII | N24: IX | O24: X | P24: XI | Q24: XII | R24: Szf | S24: M. | U24: I. | V24: II | W24: III | X24: IV | Y24: V | Z24: VI | AA24: VII | AB24: VIII | AC24: IX | AD24: X | AE24: XI | AF24: XII | AG24: + | AH24: M.
F25: szf | G25: szf | H25: szf | I25: szf | J25: szf | K25: szf | L25: szf | M25: szf | N25: szf | O25: szf | P25: szf | Q25: szf | S25: szf | U25: + | V25: + | W25: + | X25: + | Y25: + | Z25: + | AA25: + | AB25: + | AC25: + | AD25: + | AE25: + | AF25: + | AH25: +
A26: Katona László | C26: 26 | D26: 2 | E26: =SUM(B26:D26) -> 28 | F26: =B!AI4 -> 0 | G26: =B!AI28 -> 0 | H26: =B!AI52 -> 1 | I26: =B!AI76 -> 4 | J26: =B!AI100 -> 0 | K26: =B!AI124 -> 0 | L26: =B!AI148 -> 0 | M26: =B!AI172 -> 0 | N26: =B!AI196 -> 0 | O26: =B!AI220 -> 0 | P26: =B!AI244 -> 0 | Q26: =B!AI268 -> 0 | R26: =SUM(F26+G26+H26+I26+J26+K26+L26+M26+N26+O26+P26+Q26) -> 5 | S26: =SUM(E26-R26) -> 23 | U26: =B!AH4 -> 2 | V26: =B!AH28 -> 2 | W26: =B!AH52 -> 1 | X26: =B!AH76 -> 1 | Y26: =B!AH100 -> 0 | Z26: =B!AH124 -> 0 | AA26: =B!AH148 -> 0 | AB26: =B!AH172 -> 0 | AC26: =B!AH196 -> 0 | AD26: =B!AH220 -> 0 | AE26: =B!AH244 -> 0 | AF26: =B!AH268 -> 0 | AG26: =SUM(U26+V26+W26+X26+Y26+Z26+AA26+AB26+AC26+AD26+AE26+AF26) -> 6 | AH26: =SUM(16-AG26) -> 10
A27: Kiss János Tamás | C27: 30 | E27: =SUM(B27:D27) -> 30 | F27: =B!AI5 -> 0 | G27: =B!AI29 -> 1 | H27: =B!AI53 -> 3 | I27: =B!AI77 -> 1 | J27: =B!AI101 -> 0 | K27: =B!AI125 -> 0 | L27: =B!AI149 -> 0 | M27: =B!AI173 -> 0 | N27: =B!AI197 -> 0 | O27: =B!AI221 -> 0 | P27: =B!AI245 -> 0 | Q27: =B!AI269 -> 0 | R27: =SUM(F27+G27+H27+I27+J27+K27+L27+M27+N27+O27+P27+Q27) -> 5 | S27: =SUM(E27-R27) -> 25 | U27: =A!AH10 -> 1 | V27: =B!AH29 -> 1 | W27: =B!AH53 -> 1 | X27: =B!AH77 -> 1 | Y27: =B!AH101 -> 0 | Z27: =B!AH125 -> 0 | AA27: =B!AH149 -> 0 | AB27: =B!AH173 -> 0 | AC27: =B!AH197 -> 0 | AD27: =B!AH221 -> 0 | AE27: =B!AH245 -> 0 | AF27: =B!AH269 -> 0 | AG27: =SUM(U27+V27+W27+X27+Y27+Z27+AA27+AB27+AC27+AD27+AE27+AF27) -> 4 | AH27: =SUM(16-AG27) -> 12
A28: Habara Gábor | C28: 22 | E28: =SUM(B28:D28) -> 22 | F28: =B!AI6 -> 1 | G28: =B!AI30 -> 1 | H28: =B!AI54 -> 0 | I28: =B!AI78 -> 0 | J28: =B!AI102 -> 0 | K28: =B!AI126 -> 0 | L28: =B!AI150 -> 0 | M28: =B!AI174 -> 0 | N28: =B!AI198 -> 0 | O28: =B!AI222 -> 0 | P28: =B!AI246 -> 0 | Q28: =B!AI270 -> 0 | R28: =SUM(F28+G28+H28+I28+J28+K28+L28+M28+N28+O28+P28+Q28) -> 2 | S28: =SUM(E28-R28) -> 20 | U28: =B!AH6 -> 2 | V28: =B!AH30 -> 1 | W28: =B!AH54 -> 1 | X28: =B!AH78 -> 1 | Y28: =B!AH102 -> 0 | Z28: =B!AH126 -> 0 | AA28: =B!AH150 -> 0 | AB28: =B!AH174 -> 0 | AC28: =B!AH198 -> 0 | AD28: =B!AH222 -> 0 | AE28: =B!AH246 -> 0 | AF28: =B!AH270 -> 0 | AG28: =SUM(U28+V28+W28+X28+Y28+Z28+AA28+AB28+AC28+AD28+AE28+AF28) -> 5 | AH28: =SUM(16-AG28) -> 11
A29: Holba Imre | B29: 1 | C29: 30 | E29: =SUM(B29:D29) -> 31 | F29: =B!AI7 -> 1 | G29: =B!AI31 -> 0 | H29: =B!AI55 -> 3 | I29: =B!AI79 -> 14 | J29: =B!AI103 -> 0 | K29: =B!AI127 -> 0 | L29: =B!AI151 -> 0 | M29: =B!AI175 -> 0 | N29: =B!AI199 -> 0 | O29: =B!AI223 -> 0 | P29: =B!AI247 -> 0 | Q29: =B!AI271 -> 0 | R29: =SUM(F29+G29+H29+I29+J29+K29+L29+M29+N29+O29+P29+Q29) -> 18 | S29: =SUM(E29-R29) -> 13 | U29: =B!AH7 -> 1 | V29: =B!AH31 -> 2 | W29: =B!AH55 -> 0 | X29: =B!AH79 -> 1 | Y29: =B!AH103 -> 0 | Z29: =B!AH127 -> 0 | AA29: =B!AH151 -> 0 | AB29: =B!AH175 -> 0 | AC29: =B!AH199 -> 0 | AD29: =B!AH223 -> 0 | AE29: =B!AH247 -> 0 | AF29: =B!AH271 -> 0 | AG29: =SUM(U29+V29+W29+X29+Y29+Z29+AA29+AB29+AC29+AD29+AE29+AF29) -> 4 | AH29: =SUM(16-AG29) -> 12
A30: Keresztes Gyula | B30: 2 | C30: 18 | E30: =SUM(B30:D30) -> 20 | F30: =B!AI8 -> 2 | G30: =B!AI32 -> 0 | H30: =B!AI56 -> 0 | I30: =B!AI80 -> 8 | J30: =B!AI104 -> 8 | K30: =B!AI128 -> 2 | L30: =B!AI152 -> 0 | M30: =B!AI176 -> 0 | N30: =B!AI200 -> 0 | O30: =B!AI224 -> 0 | P30: =B!AI248 -> 0 | Q30: =B!AI272 -> 0 | R30: =SUM(F30+G30+H30+I30+J30+K30+L30+M30+N30+O30+P30+Q30) -> 20 | S30: =SUM(E30-R30) -> 0 | U30: =B!AH8 -> 0 | V30: =B!AH32 -> 0 | W30: =B!AH56 -> 0 | X30: =B!AH80 -> 4 | Y30: =B!AH104 -> 4 | Z30: =B!AH128 -> 0 | AA30: =B!AH152 -> 0 | AB30: =B!AH176 -> 0 | AC30: =B!AH200 -> 0 | AD30: =B!AH224 -> 0 | AE30: =B!AH248 -> 0 | AF30: =B!AH272 -> 0 | AG30: =SUM(U30+V30+W30+X30+Y30+Z30+AA30+AB30+AC30+AD30+AE30+AF30) -> 8 | AH30: =SUM(9-AG30) -> 1
A31: Király Bálint Donát | C31: 21 | E31: =SUM(B31:D31) -> 21 | F31: =B!AI9 -> 5 | G31: =B!AI33 -> 2 | H31: =B!AI57 -> 2 | I31: =B!AI81 -> 0 | J31: =B!AI105 -> 0 | K31: =B!AI129 -> 0 | L31: =B!AI153 -> 0 | M31: =B!AI177 -> 0 | N31: =B!AI201 -> 0 | O31: =B!AI225 -> 0 | P31: =B!AI249 -> 0 | Q31: =B!AI273 -> 0 | R31: =SUM(F31+G31+H31+I31+J31+K31+L31+M31+N31+O31+P31+Q31) -> 9 | S31: =SUM(E31-R31) -> 12 | U31: =B!AH9 -> 2 | V31: =B!AH33 -> 1 | W31: =B!AH57 -> 1 | X31: =B!AH81 -> 3 | Y31: =B!AH105 -> 0 | Z31: =B!AH129 -> 0 | AA31: =B!AH153 -> 0 | AB31: =B!AH177 -> 0 | AC31: =B!AH201 -> 0 | AD31: =B!AH225 -> 0 | AE31: =B!AH249 -> 0 | AF31: =B!AH273 -> 0 | AG31: =SUM(U31+V31+W31+X31+Y31+Z31+AA31+AB31+AC31+AD31+AE31+AF31) -> 7 | AH31: =SUM(16-AG31) -> 9
A32: Mezei Lajos | C32: 30 | E32: =SUM(B32:D32) -> 30 | F32: =B!AI10 -> 0 | G32: =B!AI34 -> 0 | H32: =B!AI58 -> 0 | I32: =B!AI82 -> 3 | J32: =B!AI106 -> 0 | K32: =B!AI130 -> 0 | L32: =B!AI154 -> 0 | M32: =B!AI178 -> 0 | N32: =B!AI202 -> 0 | O32: =B!AI226 -> 0 | P32: =B!AI250 -> 0 | Q32: =B!AI274 -> 0 | R32: =SUM(F32+G32+H32+I32+J32+K32+L32+M32+N32+O32+P32+Q32) -> 3 | S32: =SUM(E32-R32) -> 27 | U32: =B!AH10 -> 0 | V32: =B!AH34 -> 2 | W32: =B!AH58 -> 0 | X32: =B!AH82 -> 2 | Y32: =B!AH106 -> 0 | Z32: =B!AH130 -> 0 | AA32: =B!AH154 -> 0 | AB32: =B!AH178 -> 0 | AC32: =B!AH202 -> 0 | AD32: =B!AH226 -> 0 | AE32: =B!AH250 -> 0 | AF32: =B!AH274 -> 0 | AG32: =SUM(U32+V32+W32+X32+Y32+Z32+AA32+AB32+AC32+AD32+AE32+AF32) -> 4 | AH32: =SUM(16-AG32) -> 12
A33: Fényi László | E33: =SUM(B33:D33) -> 0 | F33: =B!AI11 -> 0 | G33: =B!AI35 -> 0 | H33: =B!AI59 -> 0 | I33: =B!AI83 -> 0 | J33: =B!AI107 -> 0 | K33: =B!AI131 -> 0 | L33: =B!AI155 -> 0 | M33: =B!AI179 -> 0 | N33: =B!AI203 -> 0 | O33: =B!AI227 -> 0 | P33: =B!AI251 -> 0 | Q33: =B!AI275 -> 0 | R33: =SUM(F33+G33+H33+I33+J33+K33+L33+M33+N33+O33+P33+Q33) -> 0 | S33: =SUM(E33-R33) -> 0 | U33: =B!AH11 -> 0 | V33: =B!AH35 -> 0 | W33: =B!AH59 -> 0 | X33: =B!AH83 -> 0 | Y33: =B!AH107 -> 0 | Z33: =B!AH131 -> 0 | AA33: =B!AH155 -> 0 | AB33: =B!AH179 -> 0 | AC33: =B!AH203 -> 0 | AD33: =B!AH227 -> 0 | AE33: =B!AH251 -> 0 | AF33: =B!AH275 -> 0 | AG33: =SUM(U33+V33+W33+X33+Y33+Z33+AA33+AB33+AC33+AD33+AE33+AF33) -> 0 | AH33: =SUM(16-AG33) -> 16
A34: Név9 | E34: =SUM(B34:D34) -> 0 | F34: =B!AI12 -> 0 | G34: =B!AI36 -> 0 | H34: =B!AI60 -> 0 | I34: =B!AI84 -> 0 | J34: =B!AI108 -> 0 | K34: =B!AI132 -> 0 | L34: =B!AI156 -> 0 | M34: =B!AI180 -> 0 | N34: =B!AI204 -> 0 | O34: =B!AI228 -> 0 | P34: =B!AI252 -> 0 | Q34: =B!AI276 -> 0 | R34: =SUM(F34+G34+H34+I34+J34+K34+L34+M34+N34+O34+P34+Q34) -> 0 | S34: =SUM(E34-R34) -> 0 | U34: =B!AH12 -> 0 | V34: =B!AH36 -> 0 | W34: =B!AH60 -> 0 | X34: =B!AH84 -> 0 | Y34: =B!AH108 -> 0 | Z34: =B!AH132 -> 0 | AA34: =B!AH156 -> 0 | AB34: =B!AH180 -> 0 | AC34: =B!AH204 -> 0 | AD34: =B!AH228 -> 0 | AE34: =B!AH252 -> 0 | AF34: =B!AH276 -> 0 | AG34: =SUM(U34+V34+W34+X34+Y34+Z34+AA34+AB34+AC34+AD34+AE34+AF34) -> 0 | AH34: =SUM(13-AG34) -> 13
A35: Név10 | E35: =SUM(B35:D35) -> 0 | F35: =B!AI13 -> 0 | G35: =B!AI37 -> 0 | H35: =B!AI61 -> 0 | I35: =B!AI85 -> 0 | J35: =B!AI109 -> 0 | K35: =B!AI133 -> 0 | L35: =B!AI157 -> 0 | M35: =B!AI181 -> 0 | N35: =B!AI205 -> 0 | O35: =B!AI229 -> 0 | P35: =B!AI253 -> 0 | Q35: =B!AI277 -> 0 | R35: =SUM(F35+G35+H35+I35+J35+K35+L35+M35+N35+O35+P35+Q35) -> 0 | S35: =SUM(E35-R35) -> 0 | U35: =B!AH13 -> 0 | V35: =B!AH37 -> 0 | W35: =B!AH61 -> 0 | X35: =B!AH85 -> 0 | Y35: =B!AH109 -> 0 | Z35: =B!AH133 -> 0 | AA35: =B!AH157 -> 0 | AB35: =B!AH181 -> 0 | AC35: =B!AH205 -> 0 | AD35: =B!AH229 -> 0 | AE35: =B!AH253 -> 0 | AF35: =B!AH277 -> 0 | AG35: =SUM(U35+V35+W35+X35+Y35+Z35+AA35+AB35+AC35+AD35+AE35+AF35) -> 0 | AH35: =SUM(13-AG35) -> 13
A36: Név11 | E36: =SUM(B36:D36) -> 0 | F36: =B!AI14 -> 0 | G36: =B!AI38 -> 0 | H36: =B!AI62 -> 0 | I36: =B!AI86 -> 0 | J36: =B!AI110 -> 0 | K36: =B!AI134 -> 0 | L36: =B!AI158 -> 0 | M36: =B!AI182 -> 0 | N36: =B!AI206 -> 0 | O36: =B!AI230 -> 0 | P36: =B!AI254 -> 0 | Q36: =B!AI278 -> 0 | R36: =SUM(F36+G36+H36+I36+J36+K36+L36+M36+N36+O36+P36+Q36) -> 0 | S36: =SUM(E36-R36) -> 0 | U36: =B!AH14 -> 0 | V36: =B!AH38 -> 0 | W36: =B!AH62 -> 0 | X36: =B!AH86 -> 0 | Y36: =B!AH110 -> 0 | Z36: =B!AH134 -> 0 | AA36: =B!AH158 -> 0 | AB36: =B!AH182 -> 0 | AC36: =B!AH206 -> 0 | AD36: =B!AH230 -> 0 | AE36: =B!AH254 -> 0 | AF36: =B!AH278 -> 0 | AG36: =SUM(U36+V36+W36+X36+Y36+Z36+AA36+AB36+AC36+AD36+AE36+AF36) -> 0 | AH36: =SUM(13-AG36) -> 13
A37: Név12 | E37: =SUM(B37:D37) -> 0 | F37: =B!AI15 -> 0 | G37: =B!AI39 -> 0 | H37: =B!AI63 -> 0 | I37: =B!AI87 -> 0 | J37: =B!AI111 -> 0 | K37: =B!AI135 -> 0 | L37: =B!AI159 -> 0 | M37: =B!AI183 -> 0 | N37: =B!AI207 -> 0 | O37: =B!AI231 -> 0 | P37: =B!AI255 -> 0 | Q37: =B!AI279 -> 0 | R37: =SUM(F37+G37+H37+I37+J37+K37+L37+M37+N37+O37+P37+Q37) -> 0 | S37: =SUM(E37-R37) -> 0 | U37: =B!AH15 -> 0 | V37: =B!AH39 -> 0 | W37: =B!AH63 -> 0 | X37: =B!AH87 -> 0 | Y37: =B!AH111 -> 0 | Z37: =B!AH135 -> 0 | AA37: =B!AH159 -> 0 | AB37: =B!AH183 -> 0 | AC37: =B!AH207 -> 0 | AD37: =B!AH231 -> 0 | AE37: =B!AH255 -> 0 | AF37: =B!AH279 -> 0 | AG37: =SUM(U37+V37+W37+X37+Y37+Z37+AA37+AB37+AC37+AD37+AE37+AF37) -> 0 | AH37: =SUM(13-AG37) -> 13
A38: Név13 | E38: =SUM(B38:D38) -> 0 | F38: =B!AI16 -> 0 | G38: =B!AI40 -> 0 | H38: =B!AI64 -> 0 | I38: =B!AI88 -> 0 | J38: =B!AI112 -> 0 | K38: =B!AI136 -> 0 | L38: =B!AI160 -> 0 | M38: =B!AI184 -> 0 | N38: =B!AI208 -> 0 | O38: =B!AI232 -> 0 | P38: =B!AI256 -> 0 | Q38: =B!AI280 -> 0 | R38: =SUM(F38+G38+H38+I38+J38+K38+L38+M38+N38+O38+P38+Q38) -> 0 | S38: =SUM(E38-R38) -> 0 | U38: =B!AH16 -> 0 | V38: =B!AH40 -> 0 | W38: =B!AH64 -> 0 | X38: =B!AH88 -> 0 | Y38: =B!AH112 -> 0 | Z38: =B!AH136 -> 0 | AA38: =B!AH160 -> 0 | AB38: =B!AH184 -> 0 | AC38: =B!AH208 -> 0 | AD38: =B!AH232 -> 0 | AE38: =B!AH256 -> 0 | AF38: =B!AH280 -> 0 | AG38: =SUM(U38+V38+W38+X38+Y38+Z38+AA38+AB38+AC38+AD38+AE38+AF38) -> 0 | AH38: =SUM(13-AG38) -> 13
A39: Név14 | E39: =SUM(B39:D39) -> 0 | F39: =B!AI17 -> 0 | G39: =B!AI41 -> 0 | H39: =B!AI65 -> 0 | I39: =B!AI89 -> 0 | J39: =B!AI113 -> 0 | K39: =B!AI137 -> 0 | L39: =B!AI161 -> 0 | M39: =B!AI185 -> 0 | N39: =B!AI209 -> 0 | O39: =B!AI233 -> 0 | P39: =B!AI257 -> 0 | Q39: =B!AI281 -> 0 | R39: =SUM(F39+G39+H39+I39+J39+K39+L39+M39+N39+O39+P39+Q39) -> 0 | S39: =SUM(E39-R39) -> 0 | U39: =B!AH17 -> 0 | V39: =B!AH41 -> 0 | W39: =B!AH65 -> 0 | X39: =B!AH89 -> 0 | Y39: =B!AH113 -> 0 | Z39: =B!AH137 -> 0 | AA39: =B!AH161 -> 0 | AB39: =B!AH185 -> 0 | AC39: =B!AH209 -> 0 | AD39: =B!AH233 -> 0 | AE39: =B!AH257 -> 0 | AF39: =B!AH281 -> 0 | AG39: =SUM(U39+V39+W39+X39+Y39+Z39+AA39+AB39+AC39+AD39+AE39+AF39) -> 0 | AH39: =SUM(13-AG39) -> 13
A40: Név15 | E40: =SUM(B40:D40) -> 0 | F40: =B!AI18 -> 0 | G40: =B!AI42 -> 0 | H40: =B!AI66 -> 0 | I40: =B!AI90 -> 0 | J40: =B!AI114 -> 0 | K40: =B!AI138 -> 0 | L40: =B!AI162 -> 0 | M40: =B!AI186 -> 0 | N40: =B!AI210 -> 0 | O40: =B!AI234 -> 0 | P40: =B!AI258 -> 0 | Q40: =B!AI282 -> 0 | R40: =SUM(F40+G40+H40+I40+J40+K40+L40+M40+N40+O40+P40+Q40) -> 0 | S40: =SUM(E40-R40) -> 0 | U40: =B!AH18 -> 0 | V40: =B!AH42 -> 0 | W40: =B!AH66 -> 0 | X40: =B!AH90 -> 0 | Y40: =B!AH114 -> 0 | Z40: =B!AH138 -> 0 | AA40: =B!AH162 -> 0 | AB40: =B!AH186 -> 0 | AC40: =B!AH210 -> 0 | AD40: =B!AH234 -> 0 | AE40: =B!AH258 -> 0 | AF40: =B!AH282 -> 0 | AG40: =SUM(U40+V40+W40+X40+Y40+Z40+AA40+AB40+AC40+AD40+AE40+AF40) -> 0 | AH40: =SUM(13-AG40) -> 13
A41: Név16 | E41: =SUM(B41:D41) -> 0 | F41: =B!AI19 -> 0 | G41: =B!AI43 -> 0 | H41: =B!AI67 -> 0 | I41: =B!AI91 -> 0 | J41: =B!AI115 -> 0 | K41: =B!AI139 -> 0 | L41: =B!AI163 -> 0 | M41: =B!AI187 -> 0 | N41: =B!AI211 -> 0 | O41: =B!AI235 -> 0 | P41: =B!AI259 -> 0 | Q41: =B!AI283 -> 0 | R41: =SUM(F41+G41+H41+I41+J41+K41+L41+M41+N41+O41+P41+Q41) -> 0 | S41: =SUM(E41-R41) -> 0 | U41: =B!AH19 -> 0 | V41: =B!AH43 -> 0 | W41: =B!AH67 -> 0 | X41: =B!AH91 -> 0 | Y41: =B!AH115 -> 0 | Z41: =B!AH139 -> 0 | AA41: =B!AH163 -> 0 | AB41: =B!AH187 -> 0 | AC41: =B!AH211 -> 0 | AD41: =B!AH235 -> 0 | AE41: =B!AH259 -> 0 | AF41: =B!AH283 -> 0 | AG41: =SUM(U41+V41+W41+X41+Y41+Z41+AA41+AB41+AC41+AD41+AE41+AF41) -> 0 | AH41: =SUM(13-AG41) -> 13
...

Sheet A
A1: JANUÁR | B1: 1 | C1: 2 | D1: 3 | E1: 4 | F1: 5 | G1: 6 | H1: 7 | I1: 8 | J1: 9 | K1: 10 | L1: 11 | M1: 12 | N1: 13 | O1: 14 | P1: 15 | Q1: 16 | R1: 17 | S1: 18 | T1: 19 | U1: 20 | V1: 21 | W1: 22 | X1: 23 | Y1: 24 | Z1: 25 | AA1: 26 | AB1: 27 | AC1: 28 | AD1: 29 | AE1: 30 | AF1: 31 | AH1: + | AI1: SZF
B2: ='2020'!B4 -> Sze | C2: ='2020'!C4 -> Cs | D2: ='2020'!D4 -> P | E2: ='2020'!E4 -> Szo | F2: ='2020'!F4 -> V | G2: ='2020'!G4 -> H | H2: ='2020'!H4 -> K | I2: ='2020'!I4 -> Sze | ... AF2: ='2020'!AF4 -> P
B3: ='2020'!B5 -> 3 | C3: ='2020'!C5 -> 3 | D3: ='2020'!D5 -> X | E3: ='2020'!E5 -> X | F3: ='2020'!F5 -> 2 | G3: ='2020'!G5 -> 2 | H3: ='2020'!H5 -> 2 | I3: ='2020'!I5 -> 2 | ... AF3: ='2020'!AF5 -> 2
A4: =ÖSSZES!$A$3 -> Csuka Lajos | D4: X | E4: X | L4: X | M4: X | S4: + | T4: X | U4: X | AB4: X | AC4: X | AF4: szf | AH4: =1*COUNTIF(A4:AF4,"+") -> 1 | AI4: =1*COUNTIF(B4:AF4,"szf") -> 1
A5: =ÖSSZES!$A$4 -> Batiz Attila | D5: X | E5: X | L5: X | M5: X | T5: X | U5: X | AA5: + | AB5: X | AC5: X | AH5: =1*COUNTIF(A5:AF5,"+") -> 1 | AI5: =1*COUNTIF(B5:AF5,"szf") -> 0
A6: =ÖSSZES!$A$5 -> Mizsák Péter | B6: szf | C6: + | D6: X | E6: X | L6: X | M6: X | T6: X | U6: X | AB6: X | AC6: X | AF6: 5.5 | AH6: =1*COUNTIF(A6:AF6,"+") -> 1 | AI6: =1*COUNTIF(B6:AF6,"szf") -> 1
A7: =ÖSSZES!$A$6 -> Füredi Antal | D7: X | E7: X | L7: X | M7: X | T7: X | U7: X | AB7: X | AC7: X | AH7: =1*COUNTIF(A7:AF7,"+") -> 0 | AI7: =1*COUNTIF(B7:AF7,"szf") -> 0
A8: =ÖSSZES!$A$7 -> Iványi István | D8: X | E8: X | F8: + | I8: 4 | K8: szf | L8: X | M8: X | T8: X | U8: X | AB8: X | AC8: X | AF8: 4 | AH8: =1*COUNTIF(A8:AF8,"+") -> 1 | AI8: =1*COUNTIF(B8:AF8,"szf") -> 1
A9: =ÖSSZES!$A$8 -> Katonka Tibor | D9: X | E9: X | L9: X | M9: X | T9: X | U9: X | AA9: + | AB9: X | AC9: X | AH9: =1*COUNTIF(A9:AF9,"+") -> 1 | AI9: =1*COUNTIF(B9:AF9,"szf") -> 0
A10: =ÖSSZES!$A$9 -> Kiss János Tamás | D10: X | E10: X | L10: X | M10: X | S10: + | T10: X | U10: X | AB10: X | AC10: X | AH10: =1*COUNTIF(A10:AF10,"+") -> 1 | AI10: =1*COUNTIF(B10:AF10,"szf") -> 0
A11: =ÖSSZES!$A$10 -> Vatamány Gergő | D11: X | E11: X | L11: X | M11: X | T11: X | U11: X | AB11: X | AC11: X | AH11: =1*COUNTIF(A11:AF11,"+") -> 0 | AI11: =1*COUNTIF(B11:AF11,"szf") -> 0
A12: =ÖSSZES!$A$11 -> Név9 | D12: X | E12: X | L12: X | M12: X | T12: X | U12: X | AB12: X | AC12: X | AH12: =1*COUNTIF(A12:AF12,"+") -> 0 | AI12: =1*COUNTIF(B12:AF12,"szf") -> 0
A13: =ÖSSZES!$A$12 -> Név10 | D13: X | E13: X | L13: X | M13: X | T13: X | U13: X | AB13: X | AC13: X | AH13: =1*COUNTIF(A13:AF13,"+") -> 0 | AI13: =1*COUNTIF(B13:AF13,"szf") -> 0
A14: =ÖSSZES!$A$13 -> Név11 | D14: X | E14: X | L14: X | M14: X | T14: X | U14: X | AB14: X | AC14: X | AH14: =1*COUNTIF(A14:AF14,"+") -> 0 | AI14: =1*COUNTIF(B14:AF14,"szf") -> 0
A15: =ÖSSZES!$A$14 -> Név12 | D15: X | E15: X | L15: X | M15: X | T15: X | U15: X | AB15: X | AC15: X | AH15: =1*COUNTIF(A15:AF15,"+") -> 0 | AI15: =1*COUNTIF(B15:AF15,"szf") -> 0
A16: =ÖSSZES!$A$15 -> Név13 | D16: X | E16: X | L16: X | M16: X | T16: X | U16: X | AB16: X | AC16: X | AH16: =1*COUNTIF(A16:AF16,"+") -> 0 | AI16: =1*COUNTIF(B16:AF16,"szf") -> 0
A17: =ÖSSZES!$A$16 -> Név14 | D17: X | E17: X | L17: X | M17: X | T17: X | U17: X | AB17: X | AC17: X | AH17: =1*COUNTIF(A17:AF17,"+") -> 0 | AI17: =1*COUNTIF(B17:AF17,"szf") -> 0
A18: =ÖSSZES!$A$17 -> Név15 | D18: X | E18: X | L18: X | M18: X | T18: X | U18: X | AB18: X | AC18: X | AH18: =1*COUNTIF(A18:AF18,"+") -> 0 | AI18: =1*COUNTIF(B18:AF18,"szf") -> 0
A19: =ÖSSZES!$A$18 -> Név16 | D19: X | E19: X | L19: X | M19: X | T19: X | U19: X | AB19: X | AC19: X | AH19: =1*COUNTIF(A19:AF19,"+") -> 0 | AI19: =1*COUNTIF(B19:AF19,"szf") -> 0
A20: =ÖSSZES!$A$19 -> Név17 | D20: X | E20: X | L20: X | M20: X | T20: X | U20: X | AB20: X | AC20: X | AH20: =1*COUNTIF(A20:AF20,"+") -> 0 | AI20: =1*COUNTIF(B20:AF20,"szf") -> 0
A21: =ÖSSZES!$A$20 -> Név18 | D21: X | E21: X | L21: X | M21: X | T21: X | U21: X | AB21: X | AC21: X | AH21: =1*COUNTIF(A21:AF21,"+") -> 0 | AI21: =1*COUNTIF(B21:AF21,"szf") -> 0
A22: =ÖSSZES!$A$21 -> Név19 | D22: X | E22: X | L22: X | M22: X | T22: X | U22: X | AB22: X | AC22: X | AH22: =1*COUNTIF(A22:AF22,"+") -> 0 | AI22: =1*COUNTIF(B22:AF22,"szf") -> 0
A23: =ÖSSZES!$A$22 -> Név20 | D23: X | E23: X | L23: X | M23: X | T23: X | U23: X | AB23: X | AC23: X | AH23: =1*COUNTIF(A23:AF23,"+") -> 0 | AI23: =1*COUNTIF(B23:AF23,"szf") -> 0
A25: FEBRUÁR | B25: 1 | C25: 2 | D25: 3 | E25: 4 | F25: 5 | G25: 6 | H25: 7 | I25: 8 | J25: 9 | K25: 10 | L25: 11 | M25: 12 | N25: 13 | O25: 14 | P25: 15 | Q25: 16 | R25: 17 | S25: 18 | T25: 19 | U25: 20 | V25: 21 | W25: 22 | X25: 23 | Y25: 24 | Z25: 25 | AA25: 26 | AB25: 27 | AC25: 28 | AD25: 29 | AH25: + | AI25: SZF
B26: ='2020'!B12 -> Szo | C26: ='2020'!C12 -> V | D26: ='2020'!D12 -> H | E26: ='2020'!E12 -> K | F26: ='2020'!F12 -> Sze | G26: ='2020'!G12 -> Cs | H26: ='2020'!H12 -> P | I26: ='2020'!I12 -> Szo | ... AD26: ='2020'!AD12 -> Szo
B27: ='2020'!B13 -> 2 | C27: ='2020'!C13 -> 2 | D27: ='2020'!D13 -> 2 | E27: ='2020'!E13 -> X | F27: ='2020'!F13 -> X | G27: ='2020'!G13 -> 1 | H27: ='2020'!H13 -> 1 | I27: ='2020'!I13 -> 1 | ... AD27: ='2020'!AD13 -> X
A28: =ÖSSZES!$A$3 -> Csuka Lajos | E28: X | F28: X | I28: + | J28: Szf | M28: X | N28: X | U28: X | V28: X | AC28: X | AD28: X | AH28: =1*COUNTIF(A28:AF28,"+") -> 1 | AI28: =1*COUNTIF(B28:AF28,"szf") -> 1
A29: =ÖSSZES!$A$4 -> Batiz Attila | E29: X | F29: X | M29: X | N29: X | U29: X | V29: X | AA29: + | AB29: + | AC29: X | AD29: X | AH29: =1*COUNTIF(A29:AF29,"+") -> 2 | AI29: =1*COUNTIF(B29:AF29,"szf") -> 0
A30: =ÖSSZES!$A$5 -> Mizsák Péter | E30: X | F30: X | M30: X | N30: X | U30: X | V30: X | AC30: X | AD30: X | AH30: =1*COUNTIF(A30:AF30,"+") -> 0 | AI30: =1*COUNTIF(B30:AF30,"szf") -> 0
A31: =ÖSSZES!$A$6 -> Füredi Antal | E31: X | F31: X | M31: X | N31: X | U31: X | V31: X | W31: + | X31: Szf | AC31: X | AD31: X | AH31: =1*COUNTIF(A31:AF31,"+") -> 1 | AI31: =1*COUNTIF(B31:AF31,"szf") -> 1
A32: =ÖSSZES!$A$7 -> Iványi István | B32: Szf | C32: + | D32: szf | E32: X | F32: X | M32: X | N32: X | P32: Szf | U32: X | V32: X | W32: B | X32: B | Y32: B | Z32: B | AA32: B | AB32: B | AC32: X | AD32: X | AH32: =1*COUNTIF(A32:AF32,"+") -> 1 | AI32: =1*COUNTIF(B32:AF32,"szf") -> 3
A33: =ÖSSZES!$A$8 -> Katonka Tibor | E33: X | F33: X | M33: X | N33: X | T33: + | U33: X | V33: X | AC33: X | AD33: X | AH33: =1*COUNTIF(A33:AF33,"+") -> 1 | AI33: =1*COUNTIF(B33:AF33,"szf") -> 0
A34: =ÖSSZES!$A$9 -> Kiss János Tamás | B34: + | E34: X | F34: X | M34: X | N34: X | U34: X | V34: X | AC34: X | AD34: X | AH34: =1*COUNTIF(A34:AF34,"+") -> 1 | AI34: =1*COUNTIF(B34:AF34,"szf") -> 0
A35: =ÖSSZES!$A$10 -> Vatamány Gergő | E35: X | F35: X | M35: X | N35: X | U35: X | V35: X | AC35: X | AD35: X | AH35: =1*COUNTIF(A35:AF35,"+") -> 0 | AI35: =1*COUNTIF(B35:AF35,"szf") -> 0
A36: =ÖSSZES!$A$11 -> Név9 | E36: X | F36: X | M36: X | N36: X | U36: X | V36: X | AC36: X | AD36: X | AH36: =1*COUNTIF(A36:AF36,"+") -> 0 | AI36: =1*COUNTIF(B36:AF36,"szf") -> 0
A37: =ÖSSZES!$A$12 -> Név10 | E37: X | F37: X | M37: X | N37: X | U37: X | V37: X | AC37: X | AD37: X | AH37: =1*COUNTIF(A37:AF37,"+") -> 0 | AI37: =1*COUNTIF(B37:AF37,"szf") -> 0
A38: =ÖSSZES!$A$13 -> Név11 | E38: X | F38: X | M38: X | N38: X | U38: X | V38: X | AC38: X | AD38: X | AH38: =1*COUNTIF(A38:AF38,"+") -> 0 | AI38: =1*COUNTIF(B38:AF38,"szf") -> 0
A39: =ÖSSZES!$A$14 -> Név12 | E39: X | F39: X | M39: X | N39: X | U39: X | V39: X | AC39: X | AD39: X | AH39: =1*COUNTIF(A39:AF39,"+") -> 0 | AI39: =1*COUNTIF(B39:AF39,"szf") -> 0
A40: =ÖSSZES!$A$15 -> Név13 | E40: X | F40: X | M40: X | N40: X | U40: X | V40: X | AC40: X | AD40: X | AH40: =1*COUNTIF(A40:AF40,"+") -> 0 | AI40: =1*COUNTIF(B40:AF40,"szf") -> 0
A41: =ÖSSZES!$A$16 -> Név14 | E41: X | F41: X | M41: X | N41: X | U41: X | V41: X | AC41: X | AD41: X | AH41: =1*COUNTIF(A41:AF41,"+") -> 0 | AI41: =1*COUNTIF(B41:AF41,"szf") -> 0
...

Sheet B
A1: JANUÁR | B1: 1 | C1: 2 | D1: 3 | E1: 4 | F1: 5 | G1: 6 | H1: 7 | I1: 8 | J1: 9 | K1: 10 | L1: 11 | M1: 12 | N1: 13 | O1: 14 | P1: 15 | Q1: 16 | R1: 17 | S1: 18 | T1: 19 | U1: 20 | V1: 21 | W1: 22 | X1: 23 | Y1: 24 | Z1: 25 | AA1: 26 | AB1: 27 | AC1: 28 | AD1: 29 | AE1: 30 | AF1: 31 | AH1: + | AI1: SZF
B2: ='2020'!B4 -> Sze | C2: ='2020'!C4 -> Cs | D2: ='2020'!D4 -> P | E2: ='2020'!E4 -> Szo | F2: ='2020'!F4 -> V | G2: ='2020'!G4 -> H | H2: ='2020'!H4 -> K | I2: ='2020'!I4 -> Sze | ... AF2: ='2020'!AF4 -> P
B3: ='2020'!B6 -> X | C3: ='2020'!C6 -> X | D3: ='2020'!D6 -> 3 | E3: ='2020'!E6 -> 3 | F3: ='2020'!F6 -> 3 | G3: ='2020'!G6 -> 3 | H3: ='2020'!H6 -> 3 | I3: ='2020'!I6 -> 3 | ... AF3: ='2020'!AF6 -> 3
A4: =ÖSSZES!$A$26 -> Katona László | B4: X | C4: X | J4: X | K4: X | N4: + | O4: + | R4: X | S4: X | Z4: X | AA4: X | AH4: =1*COUNTIF(A4:AF4,"+") -> 2 | AI4: =1*COUNTIF(B4:AF4,"szf") -> 0
A5: =ÖSSZES!$A$27 -> Kiss János Tamás | D5: X | E5: X | L5: X | M5: X | S5: + | T5: X | U5: X | AB5: X | AC5: X | AH5: =1*COUNTIF(A5:AF5,"+") -> 1 | AI5: =1*COUNTIF(B5:AF5,"szf") -> 0
A6: =ÖSSZES!$A$28 -> Habara Gábor | B6: X | C6: X | J6: X | K6: X | P6: + | Q6: + | R6: X | S6: X | V6: szf | Z6: X | AA6: X | AH6: =1*COUNTIF(A6:AF6,"+") -> 2 | AI6: =1*COUNTIF(B6:AF6,"szf") -> 1
A7: =ÖSSZES!$A$29 -> Holba Imre | B7: X | C7: X | D7: szf | J7: X | K7: X | Q7: + | R7: X | S7: X | Z7: X | AA7: X | AH7: =1*COUNTIF(A7:AF7,"+") -> 1 | AI7: =1*COUNTIF(B7:AF7,"szf") -> 1
A8: =ÖSSZES!$A$30 -> Keresztes Gyula | B8: X | C8: X | E8: szf | F8: szf | J8: X | K8: X | R8: X | S8: X | Z8: X | AA8: X | AH8: =1*COUNTIF(A8:AF8,"+") -> 0 | AI8: =1*COUNTIF(B8:AF8,"szf") -> 2
A9: =ÖSSZES!$A$31 -> Király Bálint Donát | B9: X | C9: X | D9: + | E9: + | F9: szf | G9: szf | H9: szf | I9: szf | J9: X | K9: X | R9: X | S9: X | Z9: X | AA9: X | AB9: szf | AH9: =1*COUNTIF(A9:AF9,"+") -> 2 | AI9: =1*COUNTIF(B9:AF9,"szf") -> 5
A10: =ÖSSZES!$A$32 -> Mezei Lajos | B10: X | C10: X | J10: X | K10: X | R10: X | S10: X | Z10: X | AA10: X | AH10: =1*COUNTIF(A10:AF10,"+") -> 0 | AI10: =1*COUNTIF(B10:AF10,"szf") -> 0
A11: =ÖSSZES!$A$33 -> Fényi László | B11: X | C11: X | J11: X | K11: X | R11: X | S11: X | Z11: X | AA11: X | AH11: =1*COUNTIF(A11:AF11,"+") -> 0 | AI11: =1*COUNTIF(B11:AF11,"szf") -> 0
A12: =ÖSSZES!$A$34 -> Név9 | B12: X | C12: X | J12: X | K12: X | R12: X | S12: X | Z12: X | AA12: X | AH12: =1*COUNTIF(A12:AF12,"+") -> 0 | AI12: =1*COUNTIF(B12:AF12,"szf") -> 0
A13: =ÖSSZES!$A$35 -> Név10 | B13: X | C13: X | J13: X | K13: X | R13: X | S13: X | Z13: X | AA13: X | AH13: =1*COUNTIF(A13:AF13,"+") -> 0 | AI13: =1*COUNTIF(B13:AF13,"szf") -> 0
A14: =ÖSSZES!$A$36 -> Név11 | B14: X | C14: X | J14: X | K14: X | R14: X | S14: X | Z14: X | AA14: X | AH14: =1*COUNTIF(A14:AF14,"+") -> 0 | AI14: =1*COUNTIF(B14:AF14,"szf") -> 0
A15: =ÖSSZES!$A$37 -> Név12 | B15: X | C15: X | J15: X | K15: X | R15: X | S15: X | Z15: X | AA15: X | AH15: =1*COUNTIF(A15:AF15,"+") -> 0 | AI15: =1*COUNTIF(B15:AF15,"szf") -> 0
A16: =ÖSSZES!$A$38 -> Név13 | B16: X | C16: X | J16: X | K16: X | R16: X | S16: X | Z16: X | AA16: X | AH16: =1*COUNTIF(A16:AF16,"+") -> 0 | AI16: =1*COUNTIF(B16:AF16,"szf") -> 0
A17: =ÖSSZES!$A$39 -> Név14 | B17: X | C17: X | J17: X | K17: X | R17: X | S17: X | Z17: X | AA17: X | AH17: =1*COUNTIF(A17:AF17,"+") -> 0 | AI17: =1*COUNTIF(B17:AF17,"szf") -> 0
A18: =ÖSSZES!$A$40 -> Név15 | B18: X | C18: X | J18: X | K18: X | R18: X | S18: X | Z18: X | AA18: X | AH18: =1*COUNTIF(A18:AF18,"+") -> 0 | AI18: =1*COUNTIF(B18:AF18,"szf") -> 0
A19: =ÖSSZES!$A$41 -> Név16 | B19: X | C19: X | J19: X | K19: X | R19: X | S19: X | Z19: X | AA19: X | AH19: =1*COUNTIF(A19:AF19,"+") -> 0 | AI19: =1*COUNTIF(B19:AF19,"szf") -> 0
A20: =ÖSSZES!$A$42 -> Név17 | B20: X | C20: X | J20: X | K20: X | R20: X | S20: X | Z20: X | AA20: X | AH20: =1*COUNTIF(A20:AF20,"+") -> 0 | AI20: =1*COUNTIF(B20:AF20,"szf") -> 0
A21: =ÖSSZES!$A$43 -> Név18 | B21: X | C21: X | J21: X | K21: X | R21: X | S21: X | Z21: X | AA21: X | AH21: =1*COUNTIF(A21:AF21,"+") -> 0 | AI21: =1*COUNTIF(B21:AF21,"szf") -> 0
A22: =ÖSSZES!$A$44 -> Név19 | B22: X | C22: X | J22: X | K22: X | R22: X | S22: X | Z22: X | AA22: X | AH22: =1*COUNTIF(A22:AF22,"+") -> 0 | AI22: =1*COUNTIF(B22:AF22,"szf") -> 0
A23: =ÖSSZES!$A$45 -> Név20 | B23: X | C23: X | J23: X | K23: X | R23: X | S23: X | Z23: X | AA23: X | AH23: =1*COUNTIF(A23:AF23,"+") -> 0 | AI23: =1*COUNTIF(B23:AF23,"szf") -> 0
A25: FEBRUÁR | B25: 1 | C25: 2 | D25: 3 | E25: 4 | F25: 5 | G25: 6 | H25: 7 | I25: 8 | J25: 9 | K25: 10 | L25: 11 | M25: 12 | N25: 13 | O25: 14 | P25: 15 | Q25: 16 | R25: 17 | S25: 18 | T25: 19 | U25: 20 | V25: 21 | W25: 22 | X25: 23 | Y25: 24 | Z25: 25 | AA25: 26 | AB25: 27 | AC25: 28 | AD25: 29 | AH25: + | AI25: SZF
B26: ='2020'!B12 -> Szo | C26: ='2020'!C12 -> V | D26: ='2020'!D12 -> H | E26: ='2020'!E12 -> K | F26: ='2020'!F12 -> Sze | G26: ='2020'!G12 -> Cs | H26: ='2020'!H12 -> P | I26: ='2020'!I12 -> Szo | ... AD26: ='2020'!AD12 -> Szo
B27: ='2020'!B14 -> 3 | C27: ='2020'!C14 -> X | D27: ='2020'!D14 -> X | E27: ='2020'!E14 -> 2 | F27: ='2020'!F14 -> 2 | G27: ='2020'!G14 -> 2 | H27: ='2020'!H14 -> 2 | I27: ='2020'!I14 -> 2 | ... AD27: ='2020'!AD14 -> 2
A28: =ÖSSZES!$A$26 -> Katona László | C28: X | D28: X | E28: + | F28: + | K28: X | L28: X | S28: X | T28: X | AA28: X | AB28: X | AH28: =1*COUNTIF(A28:AF28,"+") -> 2 | AI28: =1*COUNTIF(B28:AF28,"szf") -> 0
A29: =ÖSSZES!$A$27 -> Kiss János Tamás | B29: + | E29: X | F29: X | I29: szf | K29: X | L29: X | S29: X | T29: X | AA29: X | AB29: X | AH29: =1*COUNTIF(A29:AF29,"+") -> 1 | AI29: =1*COUNTIF(B29:AF29,"szf") -> 1
A30: =ÖSSZES!$A$28 -> Habara Gábor | C30: X | D30: X | K30: X | L30: X | S30: X | T30: X | AA30: X | AB30: X | AC30: + | AD30: Szf | AH30: =1*COUNTIF(A30:AF30,"+") -> 1 | AI30: =1*COUNTIF(B30:AF30,"szf") -> 1
A31: =ÖSSZES!$A$29 -> Holba Imre | C31: X | D31: X | E31: + | K31: X | L31: X | S31: X | T31: X | AA31: X | AB31: X | AD31: + | AH31: =1*COUNTIF(A31:AF31,"+") -> 2 | AI31: =1*COUNTIF(B31:AF31,"szf") -> 0
A32: =ÖSSZES!$A$30 -> Keresztes Gyula | C32: X | D32: X | K32: X | L32: X | S32: X | T32: X | AA32: X | AB32: X | AH32: =1*COUNTIF(A32:AF32,"+") -> 0 | AI32: =1*COUNTIF(B32:AF32,"szf") -> 0
A33: =ÖSSZES!$A$31 -> Király Bálint Donát | C33: X | D33: X | K33: X | L33: X | P33: + | Q33: szf | R33: szf | S33: X | T33: X | AA33: X | AB33: X | AH33: =1*COUNTIF(A33:AF33,"+") -> 1 | AI33: =1*COUNTIF(B33:AF33,"szf") -> 2
A34: =ÖSSZES!$A$32 -> Mezei Lajos | B34: + | C34: X | D34: X | K34: X | L34: X | S34: X | T34: X | AA34: X | AB34: X | AC34: + | AH34: =1*COUNTIF(A34:AF34,"+") -> 2 | AI34: =1*COUNTIF(B34:AF34,"szf") -> 0
A35: =ÖSSZES!$A$33 -> Fényi László | C35: X | D35: X | K35: X | L35: X | S35: X | T35: X | AA35: X | AB35: X | AH35: =1*COUNTIF(A35:AF35,"+") -> 0 | AI35: =1*COUNTIF(B35:AF35,"szf") -> 0
A36: =ÖSSZES!$A$34 -> Név9 | C36: X | D36: X | K36: X | L36: X | S36: X | T36: X | AA36: X | AB36: X | AH36: =1*COUNTIF(A36:AF36,"+") -> 0 | AI36: =1*COUNTIF(B36:AF36,"szf") -> 0
A37: =ÖSSZES!$A$35 -> Név10 | C37: X | D37: X | K37: X | L37: X | S37: X | T37: X | AA37: X | AB37: X | AH37: =1*COUNTIF(A37:AF37,"+") -> 0 | AI37: =1*COUNTIF(B37:AF37,"szf") -> 0
A38: =ÖSSZES!$A$36 -> Név11 | C38: X | D38: X | K38: X | L38: X | S38: X | T38: X | AA38: X | AB38: X | AH38: =1*COUNTIF(A38:AF38,"+") -> 0 | AI38: =1*COUNTIF(B38:AF38,"szf") -> 0
A39: =ÖSSZES!$A$37 -> Név12 | C39: X | D39: X | K39: X | L39: X | S39: X | T39: X | AA39: X | AB39: X | AH39: =1*COUNTIF(A39:AF39,"+") -> 0 | AI39: =1*COUNTIF(B39:AF39,"szf") -> 0
A40: =ÖSSZES!$A$38 -> Név13 | C40: X | D40: X | K40: X | L40: X | S40: X | T40: X | AA40: X | AB40: X | AH40: =1*COUNTIF(A40:AF40,"+") -> 0 | AI40: =1*COUNTIF(B40:AF40,"szf") -> 0
A41: =ÖSSZES!$A$39 -> Név14 | C41: X | D41: X | K41: X | L41: X | S41: X | T41: X | AA41: X | AB41: X | AH41: =1*COUNTIF(A41:AF41,"+") -> 0 | AI41: =1*COUNTIF(B41:AF41,"szf") -> 0
...

Sheet C
A1: JANUÁR | B1: 1 | C1: 2 | D1: 3 | E1: 4 | F1: 5 | G1: 6 | H1: 7 | I1: 8 | J1: 9 | K1: 10 | L1: 11 | M1: 12 | N1: 13 | O1: 14 | P1: 15 | Q1: 16 | R1: 17 | S1: 18 | T1: 19 | U1: 20 | V1: 21 | W1: 22 | X1: 23 | Y1: 24 | Z1: 25 | AA1: 26 | AB1: 27 | AC1: 28 | AD1: 29 | AE1: 30 | AF1: 31 | AH1: + | AI1: SZF
B2: ='2020'!B4 -> Sze | C2: ='2020'!C4 -> Cs | D2: ='2020'!D4 -> P | E2: ='2020'!E4 -> Szo | F2: ='2020'!F4 -> V | G2: ='2020'!G4 -> H | H2: ='2020'!H4 -> K | I2: ='2020'!I4 -> Sze | ... AF2: ='2020'!AF4 -> P
B3: ='2020'!B7 -> 1 | C3: ='2020'!C7 -> 1 | D3: ='2020'!D7 -> 1 | E3: ='2020'!E7 -> 1 | F3: ='2020'!F7 -> 1 | G3: ='2020'!G7 -> 1 | H3: ='2020'!H7 -> X | I3: ='2020'!I7 -> X | ... AF3: ='2020'!AF7 -> X
A4: =ÖSSZES!$A$49 -> Kuik-Filep András | C4: Szf | D4: Szf | E4: Szf | F4: Szf | G4: Szf | H4: X | I4: X | J4: Szf | P4: X | Q4: X | V4: + | W4: szf | X4: X | Y4: X | Z4: szf | AA4: szf | AF4: X | AH4: =1*COUNTIF(A4:AF4,"+") -> 1 | AI4: =1*COUNTIF(B4:AF4,"szf") -> 9
A5: =ÖSSZES!$A$50 -> Balogh Zsolt | H5: X | I5: X | P5: X | Q5: X | X5: X | Y5: X | AF5: X | AH5: =1*COUNTIF(A5:AF5,"+") -> 0 | AI5: =1*COUNTIF(B5:AF5,"szf") -> 0
A6: =ÖSSZES!$A$51 -> Éliás Viktor | B6: + | H6: X | I6: X | P6: X | Q6: X | R6: B | S6: B | T6: B | U6: B | V6: B | W6: B | X6: X | Y6: X | AF6: X | AH6: =1*COUNTIF(A6:AF6,"+") -> 1 | AI6: =1*COUNTIF(B6:AF6,"szf") -> 0
A7: =ÖSSZES!$A$52 -> Hadházi Kálmán | B7: + | H7: X | I7: X | P7: X | Q7: X | X7: X | Y7: X | AE7: szf | AF7: X | AH7: =1*COUNTIF(A7:AF7,"+") -> 1 | AI7: =1*COUNTIF(B7:AF7,"szf") -> 1
A8: =ÖSSZES!$A$53 -> Kiss Attila | H8: X | I8: X | O8: 6 | P8: X | Q8: X | X8: X | Y8: X | Z8: + | AF8: X | AH8: =1*COUNTIF(A8:AF8,"+") -> 1 | AI8: =1*COUNTIF(B8:AF8,"szf") -> 0
A9: =ÖSSZES!$A$54 -> Serestyén Dániel | B9: + | C9: szf | H9: X | I9: X | P9: X | Q9: X | X9: X | Y9: X | AF9: X | AH9: =1*COUNTIF(A9:AF9,"+") -> 1 | AI9: =1*COUNTIF(B9:AF9,"szf") -> 1
A10: =ÖSSZES!$A$55 -> Varga Imre | H10: X | I10: X | K10: + | P10: X | Q10: X | X10: X | Y10: X | AC10: 5.5 | AF10: X | AH10: =1*COUNTIF(A10:AF10,"+") -> 1 | AI10: =1*COUNTIF(B10:AF10,"szf") -> 0
A11: =ÖSSZES!$A$56 -> Név8 | H11: X | I11: X | P11: X | Q11: X | X11: X | Y11: X | AF11: X | AH11: =1*COUNTIF(A11:AF11,"+") -> 0 | AI11: =1*COUNTIF(B11:AF11,"szf") -> 0
A12: =ÖSSZES!$A$57 -> Név9 | H12: X | I12: X | P12: X | Q12: X | X12: X | Y12: X | AF12: X | AH12: =1*COUNTIF(A12:AF12,"+") -> 0 | AI12: =1*COUNTIF(B12:AF12,"szf") -> 0
A13: =ÖSSZES!$A$58 -> Név10 | H13: X | I13: X | P13: X | Q13: X | X13: X | Y13: X | AF13: X | AH13: =1*COUNTIF(A13:AF13,"+") -> 0 | AI13: =1*COUNTIF(B13:AF13,"szf") -> 0
A14: =ÖSSZES!$A$59 -> Név11 | H14: X | I14: X | P14: X | Q14: X | X14: X | Y14: X | AF14: X | AH14: =1*COUNTIF(A14:AF14,"+") -> 0 | AI14: =1*COUNTIF(B14:AF14,"szf") -> 0
A15: =ÖSSZES!$A$60 -> Név12 | H15: X | I15: X | P15: X | Q15: X | X15: X | Y15: X | AF15: X | AH15: =1*COUNTIF(A15:AF15,"+") -> 0 | AI15: =1*COUNTIF(B15:AF15,"szf") -> 0
A16: =ÖSSZES!$A$61 -> Név13 | H16: X | I16: X | P16: X | Q16: X | X16: X | Y16: X | AF16: X | AH16: =1*COUNTIF(A16:AF16,"+") -> 0 | AI16: =1*COUNTIF(B16:AF16,"szf") -> 0
A17: =ÖSSZES!$A$62 -> Név14 | H17: X | I17: X | P17: X | Q17: X | X17: X | Y17: X | AF17: X | AH17: =1*COUNTIF(A17:AF17,"+") -> 0 | AI17: =1*COUNTIF(B17:AF17,"szf") -> 0
A18: =ÖSSZES!$A$63 -> Név15 | H18: X | I18: X | P18: X | Q18: X | X18: X | Y18: X | AF18: X | AH18: =1*COUNTIF(A18:AF18,"+") -> 0 | AI18: =1*COUNTIF(B18:AF18,"szf") -> 0
A19: =ÖSSZES!$A$64 -> Név16 | H19: X | I19: X | P19: X | Q19: X | X19: X | Y19: X | AF19: X | AH19: =1*COUNTIF(A19:AF19,"+") -> 0 | AI19: =1*COUNTIF(B19:AF19,"szf") -> 0
A20: =ÖSSZES!$A$65 -> Név17 | H20: X | I20: X | P20: X | Q20: X | X20: X | Y20: X | AF20: X | AH20: =1*COUNTIF(A20:AF20,"+") -> 0 | AI20: =1*COUNTIF(B20:AF20,"szf") -> 0
A21: =ÖSSZES!$A$66 -> Név18 | H21: X | I21: X | P21: X | Q21: X | X21: X | Y21: X | AF21: X | AH21: =1*COUNTIF(A21:AF21,"+") -> 0 | AI21: =1*COUNTIF(B21:AF21,"szf") -> 0
A22: =ÖSSZES!$A$67 -> Név19 | H22: X | I22: X | P22: X | Q22: X | X22: X | Y22: X | AF22: X | AH22: =1*COUNTIF(A22:AF22,"+") -> 0 | AI22: =1*COUNTIF(B22:AF22,"szf") -> 0
A23: =ÖSSZES!$A$68 -> Név20 | H23: X | I23: X | P23: X | Q23: X | X23: X | Y23: X | AF23: X | AH23: =1*COUNTIF(A23:AF23,"+") -> 0 | AI23: =1*COUNTIF(B23:AF23,"szf") -> 0
A25: FEBRUÁR | B25: 1 | C25: 2 | D25: 3 | E25: 4 | F25: 5 | G25: 6 | H25: 7 | I25: 8 | J25: 9 | K25: 10 | L25: 11 | M25: 12 | N25: 13 | O25: 14 | P25: 15 | Q25: 16 | R25: 17 | S25: 18 | T25: 19 | U25: 20 | V25: 21 | W25: 22 | X25: 23 | Y25: 24 | Z25: 25 | AA25: 26 | AB25: 27 | AC25: 28 | AD25: 29 | AH25: + | AI25: SZF
